Workbook

Sheet Rev
B2: Rev | C2: Date | D2: Update description
B3: 0.00 | C3: 44881 | D3: copy from “GDMA_A2_DES_REG_v2.7.xlsx”
B4: 0.01 | D4: (1) 增加 CSR base_addr_region 至 32 个 (2) 修改 DMA_tensor 指令
B5: 0.03 | D5: 增加 randgen/randmask 指令 descriptor
B6: 0.04 | D6: 修改 CSR 寄存器： (1) 增加副线程 descriptor 寄存器 (2) 将地址增加至 40bits (3) 增加 compress_wqos / decompress_rqos (4) 增加有多管 rdma_ctrl 指令的 slot memory 的分配寄存器 (5) 删除一组 ddr qos 寄存器，只留下一组
B7: 0.05 | D7: 修改gather/scatter指令 （1）增加idx的UINT64类型 （2）增加gather/scatter地址描述
B8: 0.06 | D8: 修改gather/scatter指令 （1）删除idx的UINT64类型 （2）修改gather/scatter cmd_type field，与其他指令对齐 （3）增加scatter inplace/add special_func
B9: 0.07 | D9: 新增GDMA_VBD指令
B10: 0.08 | D10: CSR寄存器新增cdma_vde_bypass
B11: 0.09 | C11: 45177 | D11: 新增CSR寄存器master_des_addr_update，slave_des_addr_updata；修改des_clr为rw类型，修改ins_buf_one_forth_full，ins_buf_three_forth_full, ins_buf_empty_full, ins_buf_full为rwc类型, 修改cfg_load_mon_clr为rws类型
B12: 0.10 | C12: 45180 | D12: CSR Table新增寄存器：randmask_seed[63:0]和randmask_seed_enable，type为rw
B13: 0.11 | C13: 45181 | D13: CSR Table: des_mode_enable, sync_id_reset, des_clr, master/slave_des_addr_l32, word_nums_after_filter, ins_buff_empty, ins_buf_one_fouth_full, ins_buff_three_forth_full, ins_buff_full, cfg_load_mon_clr的description添加A2到sg2260的r/w type修改；表格下方添加寄存器类型说明。
B14: 0.12 | C14: 45181 | D14: CSR Table新增mst/slv_des_addr,a4s_dest_id,a4s_src_id寄存器，修改message_base_id为9bit
B15: 0.13 | C15: 45184 | D15: 新增DES指令：lossy_compress, lossy_decompress。
B16: 0.14 | C16: 45187 | D16: 修改各指令 DES (1) 增加 cache_en / cache_flush 位段 (2) 修改 cmd_type 至 5bits (3) 修改 addr 至 40bits，并修改描述
B17: 0.15 | C17: 45188 | D17: CSR寄存器：current_sync_id, intr_sync_id位宽24bit修改为32bit。其中intr_sync_id地址从gdma_csr_11移至gdma_csr_69。DES指令：cmd_id_dep位宽24bit->17bit。
B18: 0.18 | C18: 45189 | D18: scatter / compress / lossy_decompress / decompress 地址 40bit 修正至 45bit
B19: 0.19 | C19: 45189 | D19: DMA_sys指令constant value栏位描述中，message_id修改为9bit，wcnt和scnt修改为6bit
B20: 0.20 | C20: 45190 | D20: (1) DES cmd_type 删除 send (2) 增加 transfer 指令描述
B21: 0.21 | C21: 45197 | D21: DMA_sys指令cmd_special_function位段新增sys_fork/join/exit指令
B22: 0.22 | C22: 45211 | D22: CSR： 修改current_sync_id为mst_current_sync_id，添加slv_current_sync_id， 修改intr_sync_id为mst_intr_sync_id，添加slv_intr_sync_id， 修改ins_buf_status为mst_ins_buf_status,添加slv_ins_buf_status, DMA_sys: wcnt和scnt从6bit修改为7bit,
... B26: 0.26 | C26: 45218 | D26: CSR: err interrupt增加mst/slv_depend_id_err和相应的_disable寄存器；
B27: 0.27 | C27: 203/10/20 | D27: CSR： des_clr更改为rws类型；
B28: 0.28 | C28: 45219 | D28: Randmask指令增加FP8格式
B29: 0.29 | C29: 45219 | D29: CSR: 1.增加gdma_csr_76位段8个寄存器；
B30: 0.3 | C30: 45220 | D30: DES: 1.增加 tensor / lossy_compress / lossy_decompress 指令 all_reduce_code 位段
B31: 0.31 | C31: 45220 | D31: CSR： 1.删除a4s_src_id register；
B32: 0.32 | C32: 45223 | D32: sys指令：constant value删除tdest_id位段
B33: 0.33 | C33: 45229 | D33: CSR：增加des_mode_set_err和对应的disable寄存器
B34: 0.46 | C34: 45231 | D34: 1.删除 tensor 指令 distribute 描述 2.各指令 data_format 扩展为 4 bit 3.各指令 data_format 均只描述会用到的数据类型 4.增加对 tensor [63:48] [703:656] reserve 位在 GDMA 必须配 0 的描述，描述放在 templete 分页
B35: 0.47 | C35: 45234 | D35: CSR: interrupt增加thrd_cmd_cfg_err
B36: 0.48 | C36: 45236 | D36: 增加gather/scatter的start_pos寄存器
B37: 0.49 | C37: 45237 | D37: 增加randmask指令的init_seed寄存器
B38: 0.5 | C38: 45237 | D38: CSR：增加verify列，标记需要验证的register，没有其他作用
B39: 0.51 | C39: 45238 | D39: 修改 tensor 指令对 cdma reserve 位段 tie0 的描述
... B64: 0.76 | C64: 45317 | D64: CSR: h264地址增加ar_latency_th
B65: 0.77 (2260E) | C65: 45712 | D65: CSR： 1. 更改 message_base_id 寄存器地址 2. message_base_id/slv_message_base_id 由 9bit 扩展至 10bit 指令： 1. masked_select / nonzero 指令 h/w size 扩展为 32bit 2. general 指令普通搬运增加 nchw 模式，broadcast 增加 nhw 模式 3. sys 指令 message_id 由 9bit 扩展为 10bit，scnt/wcnd 基础位置更改为 constant value 的 bit16 4. 修正 src/dst/mask/index 的地址描述
B66: 0.77 (2260E) | C66: 45737 | D66: 指令： 1. lossy_compress / lossy_decompress 指令原 bit511~bit448 reserve 位段，修改为 src n/c/h/w size

Sheet template
A1: Field | B1: Length（bit） | C1: High （bit） | D1: Low （bit） | E1: SW Offset address | F1: SW High(bit) | G1: SW Low（bit） | H1: RW | I1: descriptions
A2: intr_en | B2: 1 | C2: =D2+B2-1 -> 0 | D2: 0 | E2: =ROUNDDOWN(C2/32,0) -> 0 | F2: =C2-E2*32 -> 0 | G2: =D2-E2*32 -> 0 | H2: RW | I2: Interrupt Enable;if this bit is set, CPU COULD get interrupt when the instruction is finished 0: disable interrupt 1: enable interrupt
A3: stride_enable | B3: 1 | C3: =D3+B3-1 -> 1 | D3: =INDIRECT(ADDRESS(ROW()-1,COLUMN()-1))+1 -> 1 | E3: =ROUNDDOWN(C3/32,0) -> 0 | F3: =C3-E3*32 -> 1 | G3: =D3-E3*32 -> 1 | H3: RW | I3: Stride enable 0：No stride for all blob definition 1：Enable stride for all blob definition
A4: nchw_copy | B4: 1 | C4: =D4+B4-1 -> 2 | D4: =INDIRECT(ADDRESS(ROW()-1,COLUMN()-1))+1 -> 2 | E4: =ROUNDDOWN(C4/32,0) -> 0 | F4: =C4-E4*32 -> 2 | G4: =D4-E4*32 -> 2 | H4: RW | I4: NCHW copy bit 0: use separate src and dst NCHW value setting 1: reuse src NCHW value for dst NCHW value
A5: cmd_long | B5: 1 | C5: =D5+B5-1 -> 3 | D5: =INDIRECT(ADDRESS(ROW()-1,COLUMN()-1))+1 -> 3 | E5: =ROUNDDOWN(C5/32,0) -> 0 | F5: =C5-E5*32 -> 3 | G5: =D5-E5*32 -> 3 | H5: RW | I5: 0:768bit full cmd; 1:128/256/384/512 short cmd
A6: cache_en | B6: 1 | C6: =D6+B6-1 -> 4 | D6: =INDIRECT(ADDRESS(ROW()-1,COLUMN()-1))+1 -> 4 | E6: =ROUNDDOWN(C6/32,0) -> 0 | F6: =C6-E6*32 -> 4 | G6: =D6-E6*32 -> 4 | H6: RW | I6: Read cache enable 0: Read not use cache 1: Read use cache
A7: cache_flush | B7: 1 | C7: =D7+B7-1 -> 5 | D7: =INDIRECT(ADDRESS(ROW()-1,COLUMN()-1))+1 -> 5 | E7: =ROUNDDOWN(C7/32,0) -> 0 | F7: =C7-E7*32 -> 5 | G7: =D7-E7*32 -> 5 | H7: RW | I7: Flush cache 0: Not Flush cache 1: Flush cache
A8: reserved | B8: 2 | C8: 7 | D8: =INDIRECT(ADDRESS(ROW()-1,COLUMN()-1))+1 -> 6 | E8: =ROUNDDOWN(C8/32,0) -> 0 | F8: =C8-E8*32 -> 7 | G8: =D8-E8*32 -> 6 | H8: RO | I8: reserved
A9: bid_in_order | B9: 1 | C9: =D9+B9-1 -> 8 | D9: 8 | E9: 0 | F9: 8 | G9: 8 | H9: RW
A10: bw_lmt_rd | B10: 1 | C10: =D10+B10-1 -> 9 | D10: 9 | E10: 0 | F10: 9 | G10: 9 | H10: RW
A11: bw_lmt_wr | B11: 1 | C11: =D11+B11-1 -> 10 | D11: 10 | E11: 0 | F11: 10 | G11: 10 | H11: RW
A12: early_resp_dis | B12: 1 | C12: 11 | D12: 11 | E12: 0 | F12: 11 | G12: 11 | H12: RW
A13: Reserved | B13: 20 | C13: 31 | D13: =INDIRECT(ADDRESS(ROW()-1,COLUMN()-1))+1 -> 12 | E13: =ROUNDDOWN(C13/32,0) -> 0 | F13: =C13-E13*32 -> 31 | G13: =D13-E13*32 -> 12 | H13: RO | I13: reserved
A14: cmd_type | B14: 5 | C14: =D14+B14-1 -> 36 | D14: =INDIRECT(ADDRESS(ROW()-1,COLUMN()-1))+1 -> 32 | E14: =ROUNDDOWN(C14/32,0) -> 1 | F14: =C14-E14*32 -> 4 | G14: =D14-E14*32 -> 0 | H14: RW | I14: 0x0:GDMA_tensor 0x1:GDMA_matrix 0x2:GDMA_masked_select 0x3:GDMA_general 0x5:GDMA_nonzero 0x6:GDMA_sys 0x7:GDMA_gather 0x8:GDMA_scatter 0x9:GDMA_reverse 0xc:GDMA_lossy_compress 0xd:GDMA_lossy_decompress
A15: cmd_special_function | B15: 3 | C15: =D15+B15-1 -> 39 | D15: =INDIRECT(ADDRESS(ROW()-1,COLUMN()-1))+1 -> 37 | E15: =ROUNDDOWN(C15/32,0) -> 1 | F15: =C15-E15*32 -> 7 | G15: =D15-E15*32 -> 5 | H15: RW | I15: this field is connected with cmd_type. when cmd_type == DMA_tensor 000: No special function 001: Enable transposition write (For Neuron transposition case, the dest_N= src_C, dest_C=src_N) 011: broadcast：only support C size<=64 and lmem mask invalid others: reserved
A16: fill_constant_en | B16: 1 | C16: =D16+B16-1 -> 40 | D16: =INDIRECT(ADDRESS(ROW()-1,COLUMN()-1))+1 -> 40 | E16: =ROUNDDOWN(C16/32,0) -> 1 | F16: =C16-E16*32 -> 8 | G16: =D16-E16*32 -> 8 | H16: RW | I16: 0: no fill constant 1: fill constant enable
A17: src_data_format | B17: 4 | C17: =D17+B17-1 -> 44 | D17: =INDIRECT(ADDRESS(ROW()-1,COLUMN()-1))+1 -> 41 | E17: =ROUNDDOWN(C17/32,0) -> 1 | F17: =C17-E17*32 -> 12 | G17: =D17-E17*32 -> 9 | H17: RW | I17: Source Data Format 0:INT8 1:FP16 2:FP32 3:INT16 4:INT32 5:BFP16 6:FP20 7:FP8 E4M3 8:FP8 E5M2 others：not support
A18: reserved | B18: 3 | C18: =D18+B18-1 -> 47 | D18: =INDIRECT(ADDRESS(ROW()-1,COLUMN()-1))+1 -> 45 | E18: =ROUNDDOWN(C18/32,0) -> 1 | F18: =C18-E18*32 -> 15 | G18: =D18-E18*32 -> 13 | H18: RO | I18: reserved
A19: reserved | B19: 16 | C19: =D19+B19-1 -> 63 | D19: =INDIRECT(ADDRESS(ROW()-1,COLUMN()-1))+1 -> 48 | E19: =ROUNDDOWN(C19/32,0) -> 1 | F19: =C19-E19*32 -> 31 | G19: =D19-E19*32 -> 16 | H19: RO | I19: reserved (for CDMA src_hsize[31:16], GDMA must tie 0)
A20: cmd_id_dep | B20: 17 | C20: =D20+B20-1 -> 80 | D20: =INDIRECT(ADDRESS(ROW()-1,COLUMN()-1))+1 -> 64 | E20: =ROUNDDOWN(C20/32,0) -> 2 | F20: =C20-E20*32 -> 16 | G20: =D20-E20*32 -> 0 | H20: RW | I20: Execution of this descriptor need to wait for engine[i]'s cmd_id which depends on the cmd_id_en to be bigger than the ID specified in this field. [15:0] is depend_id, [16] is depend_id_enable(0:disable; 1:enable)
A21: reserved | B21: 6 | C21: 86 | D21: 81 | E21: =ROUNDDOWN(C21/32,0) -> 2 | F21: 22 | G21: =D21-E21*32 -> 17 | H21: RO | I21: reserved
A22: break_point | B22: 1 | C22: 87 | D22: 87 | E22: 2 | F22: 23 | G22: 23 | H22: RW | I22: when dbg_mode equals to 2'b10 and this bit is 1, the gdma will stop executing the next descriptor after this descriptor is executed,
A23: reserved | B23: 8 | C23: =D23+B23-1 -> 95 | D23: =INDIRECT(ADDRESS(ROW()-1,COLUMN()-1))+1 -> 88 | E23: =ROUNDDOWN(C23/32,0) -> 2 | F23: 31 | G23: =D23-E23*32 -> 24 | H23: RO | I23: reserved
A24: constant_value | B24: 32 | C24: =D24+B24-1 -> 127 | D24: =INDIRECT(ADDRESS(ROW()-1,COLUMN()-1))+1 -> 96 | E24: =ROUNDDOWN(C24/32,0) -> 3 | F24: =C24-E24*32 -> 31 | G24: =D24-E24*32 -> 0 | H24: RW | I24: when cmd_special_function==fill constant, this field means constant value
A25: src_nstride | B25: 32 | C25: =D25+B25-1 -> 159 | D25: =INDIRECT(ADDRESS(ROW()-1,COLUMN()-1))+1 -> 128 | E25: =ROUNDDOWN(C25/32,0) -> 4 | F25: =C25-E25*32 -> 31 | G25: =D25-E25*32 -> 0 | H25: RW | I25: unsigned number; Source blob N stride
A26: src_cstride | B26: 32 | C26: =D26+B26-1 -> 191 | D26: =INDIRECT(ADDRESS(ROW()-1,COLUMN()-1))+1 -> 160 | E26: =ROUNDDOWN(C26/32,0) -> 5 | F26: =C26-E26*32 -> 31 | G26: =D26-E26*32 -> 0 | H26: RW | I26: unsigned number. Source blob C stride
A27: src_hstride | B27: 32 | C27: =D27+B27-1 -> 223 | D27: =INDIRECT(ADDRESS(ROW()-1,COLUMN()-1))+1 -> 192 | E27: =ROUNDDOWN(C27/32,0) -> 6 | F27: =C27-E27*32 -> 31 | G27: =D27-E27*32 -> 0 | H27: RW | I27: unsigned number; Source blob H stride
A28: src_wstride | B28: 32 | C28: =D28+B28-1 -> 255 | D28: =INDIRECT(ADDRESS(ROW()-1,COLUMN()-1))+1 -> 224 | E28: =ROUNDDOWN(C28/32,0) -> 7 | F28: =C28-E28*32 -> 31 | G28: =D28-E28*32 -> 0 | H28: RW | I28: unsigned number; Source blob W stride
A29: dst_nstride | B29: 32 | C29: =D29+B29-1 -> 287 | D29: =INDIRECT(ADDRESS(ROW()-1,COLUMN()-1))+1 -> 256 | E29: =ROUNDDOWN(C29/32,0) -> 8 | F29: =C29-E29*32 -> 31 | G29: =D29-E29*32 -> 0 | H29: RW | I29: unsigned number; desitination blob N stride
A30: dst_cstride | B30: 32 | C30: =D30+B30-1 -> 319 | D30: =INDIRECT(ADDRESS(ROW()-1,COLUMN()-1))+1 -> 288 | E30: =ROUNDDOWN(C30/32,0) -> 9 | F30: =C30-E30*32 -> 31 | G30: =D30-E30*32 -> 0 | H30: RW | I30: unsigned number.desitination blob C stride
A31: dst_hstride | B31: 32 | C31: =D31+B31-1 -> 351 | D31: =INDIRECT(ADDRESS(ROW()-1,COLUMN()-1))+1 -> 320 | E31: =ROUNDDOWN(C31/32,0) -> 10 | F31: =C31-E31*32 -> 31 | G31: =D31-E31*32 -> 0 | H31: RW | I31: unsigned number; desitination blob H stride
A32: dst_wstride | B32: 32 | C32: =D32+B32-1 -> 383 | D32: =INDIRECT(ADDRESS(ROW()-1,COLUMN()-1))+1 -> 352 | E32: =ROUNDDOWN(C32/32,0) -> 11 | F32: =C32-E32*32 -> 31 | G32: =D32-E32*32 -> 0 | H32: RW | I32: unsigned number; desitination blob W stride
A33: src_nsize | B33: 16 | C33: =D33+B33-1 -> 399 | D33: =INDIRECT(ADDRESS(ROW()-1,COLUMN()-1))+1 -> 384 | E33: =ROUNDDOWN(C33/32,0) -> 12 | F33: =C33-E33*32 -> 15 | G33: =D33-E33*32 -> 0 | H33: RW | I33: Source Blob Number
A34: src_csize | B34: 16 | C34: =D34+B34-1 -> 415 | D34: =INDIRECT(ADDRESS(ROW()-1,COLUMN()-1))+1 -> 400 | E34: =ROUNDDOWN(C34/32,0) -> 12 | F34: =C34-E34*32 -> 31 | G34: =D34-E34*32 -> 16 | H34: RW | I34: Source blob C
A35: src_hsize | B35: 16 | C35: =D35+B35-1 -> 431 | D35: =INDIRECT(ADDRESS(ROW()-1,COLUMN()-1))+1 -> 416 | E35: =ROUNDDOWN(C35/32,0) -> 13 | F35: =C35-E35*32 -> 15 | G35: =D35-E35*32 -> 0 | H35: RW | I35: Source blob H
... A41: src_start_addr_l32 | B41: 32 | C41: =D41+B41-1 -> 543 | D41: =INDIRECT(ADDRESS(ROW()-1,COLUMN()-1))+1 -> 512 | E41: =ROUNDDOWN(C41/32,0) -> 16 | F41: =C41-E41*32 -> 31 | G41: =D41-E41*32 -> 0 | H41: RW | I41: source blob start address[31:0]
A42: src_start_addr_h13 | B42: 13 | C42: 556 | D42: 544 | E42: 17 | F42: 12 | G42: 0 | H42: RW | I42: bit[7:0]=source blob start address[39:32] bit[12:8]=0: real address = start address[39:0] + csr_region[0]<<8 bit[12:8]=1: real address = start address[39:0] + csr_region[1]<<8 bit[12:8]=2: real address = start address[39:0] + csr_region[2]<<8 bit[12:8]=3: real address = start address[39:0] + csr_region[3]<<8 bit[12:8]=4: real address = start address[39:0] + csr_region[4]<<8 bit[12:8]=5: real address = start address[39:0] + csr_region[5]<<8 bit[12:8]=6: real address = start address[39:0] + csr_region[6]<<8 bit[12:8]=7: real address = start address[39:0] + csr_region[7]<<8 bit[12:8]=8: real address = start address[39:0] + csr_region[8]<<8 bit[12:8]=9: real address = start address[39:0] + csr_region[9]<<8 bit[12:8]=10: real address = start address[39:0] + csr_region[10]<<8 bit[12:8]=11: real address = start address[39:0] + csr_region[11]<<8 bit[12:8]=12: real address = start address[39:0] + csr_region[12]<<8 bit[12:8]=13: real address = start address[39:0] + csr_region[13]<<8 bit[12:8]=14: real address = start address[39:0] + csr_region[14]<<8 bit[12:8]=15: real address = start address[39:0] + csr_region[15]<<8 bit[12:8]=16: real address = start address[39:0] + csr_region[16]<<8 bit[12:8]=17: real address = start address[39:0] + csr_region[17]<<8 bit[12:8]=18: real address = start address[39:0] + csr_region[18]<<8 bit[12:8]=19: real address = start address[39:0] + csr_region[19]<<8 bit[12:8]=20: real address = start address[39:0] + csr_region[20]<<8 bit[12:8]=21: real address = start address[39:0] + csr_region[21]<<8 bit[12:8]=22: real address = start address[39:0] + csr_region[22]<<8 bit[12:8]=23: real address = start address[39:0] + csr_region[23]<<8 bit[12:8]=24: real address = start address[39:0] + csr_region[24]<<8 bit[12:8]=25: real address = start address[39:0] + csr_region[25]<<8 bit[12:8]=26: real address = start address[39:0] + csr_region[26]<<8 bit[12:8]=27: real address = start address[39:0] + csr_region[27]<<8 bit[12:8]=28: real address = start address[39:0] + csr_region[28]<<8 bit[12:8]=29: real address = start address[39:0] + csr_region[29]<<8 bit[12:8]=30: real address = start address[39:0] + csr_region[30]<<8 bit[12:8]=31: real address = start address[39:0] real address[39:32] == 'h69 & bit[12:8]==31 means src is tiu, otherwise, src is from DTN
A43: reserved | B43: 19 | C43: =D43+B43-1 -> 575 | D43: =INDIRECT(ADDRESS(ROW()-1,COLUMN()-1))+1 -> 557 | E43: =ROUNDDOWN(C43/32,0) -> 17 | F43: =C43-E43*32 -> 31 | G43: =D43-E43*32 -> 13 | H43: RW | I43: reserved
A44: dst_start_addr_l32 | B44: 32 | C44: =D44+B44-1 -> 607 | D44: =INDIRECT(ADDRESS(ROW()-1,COLUMN()-1))+1 -> 576 | E44: =ROUNDDOWN(C44/32,0) -> 18 | F44: =C44-E44*32 -> 31 | G44: =D44-E44*32 -> 0 | H44: RW | I44: destination blob start address[31:0]
A45: dst_start_addr_h13 | B45: 13 | C45: 620 | D45: 608 | E45: 19 | F45: 12 | G45: 0 | H45: RW | I45: bit[7:0]=destination blob start address[39:32] bit[12:8]=0: real address = start address[39:0] + csr_region[0]<<8 bit[12:8]=1: real address = start address[39:0] + csr_region[1]<<8 bit[12:8]=2: real address = start address[39:0] + csr_region[2]<<8 bit[12:8]=3: real address = start address[39:0] + csr_region[3]<<8 bit[12:8]=4: real address = start address[39:0] + csr_region[4]<<8 bit[12:8]=5: real address = start address[39:0] + csr_region[5]<<8 bit[12:8]=6: real address = start address[39:0] + csr_region[6]<<8 bit[12:8]=7: real address = start address[39:0] + csr_region[7]<<8 bit[12:8]=8: real address = start address[39:0] + csr_region[8]<<8 bit[12:8]=9: real address = start address[39:0] + csr_region[9]<<8 bit[12:8]=10: real address = start address[39:0] + csr_region[10]<<8 bit[12:8]=11: real address = start address[39:0] + csr_region[11]<<8 bit[12:8]=12: real address = start address[39:0] + csr_region[12]<<8 bit[12:8]=13: real address = start address[39:0] + csr_region[13]<<8 bit[12:8]=14: real address = start address[39:0] + csr_region[14]<<8 bit[12:8]=15: real address = start address[39:0] + csr_region[15]<<8 bit[12:8]=16: real address = start address[39:0] + csr_region[16]<<8 bit[12:8]=17: real address = start address[39:0] + csr_region[17]<<8 bit[12:8]=18: real address = start address[39:0] + csr_region[18]<<8 bit[12:8]=19: real address = start address[39:0] + csr_region[19]<<8 bit[12:8]=20: real address = start address[39:0] + csr_region[20]<<8 bit[12:8]=21: real address = start address[39:0] + csr_region[21]<<8 bit[12:8]=22: real address = start address[39:0] + csr_region[22]<<8 bit[12:8]=23: real address = start address[39:0] + csr_region[23]<<8 bit[12:8]=24: real address = start address[39:0] + csr_region[24]<<8 bit[12:8]=25: real address = start address[39:0] + csr_region[25]<<8 bit[12:8]=26: real address = start address[39:0] + csr_region[26]<<8 bit[12:8]=27: real address = start address[39:0] + csr_region[27]<<8 bit[12:8]=28: real address = start address[39:0] + csr_region[28]<<8 bit[12:8]=29: real address = start address[39:0] + csr_region[29]<<8 bit[12:8]=30: real address = start address[39:0] + csr_region[30]<<8 bit[12:8]=31: real address = start address[39:0] real address[39:32] == 'h69 & bit[12:8]==31 means dst is tiu, otherwise, dst is DTN
...

Sheet CSR Table
A1: Project Name | B1: GDMA
A2: Sub system | B2: regcfg
A3: Module Name | B3: gdma_csr
A4: Address Width | B4: 16
A5: Data Width | B5: 32
A6: Address bytes alignment | B6: 1
A7: Main Clock | B7: pclk
A8: Main Reset | B8: presetn
A9: File Version | B9: version 0.08
A10: Creation Date | B10: 8/29/2023
A11: Base Address | B11: h58000000
A12: //
A13: //Begin
A14: Reg High Address | B14: Reg Low Address | C14: Register Name | D14: Short Description | E14: Register Description | F14: Reset | G14: Field Name | H14: verify | I14: MSB | J14: LSB | K14: Bits | L14: Init | M14: r/w | N14: Field Description | O14: output but not used in gdma_top | P14: Mask | Q14: check value | R14: shadow | S14: shadow ctrl | T14: shadow read | U14: cross clock | V14: cross rst | W14: group | X14: Visibility
A15: h0 | B15: h0 | C15: gdma_csr_0 | F15: presetn | G15: des_mode_enable | I15: 0 | J15: 0 | K15: 1 | L15: h0 | M15: rws | N15: 0: gdma in PIO mode 1: gdma in DES mode A2:WSC -> 2260:rws | O15: no
F16: presetn | G16: sync_id_reset | I16: 1 | J16: 1 | K16: 1 | L16: h0 | M16: w1p | N16: 0: Do not reset the SyncID output 1: Reset the SyncID output to be all 0s This bit will be cleared immediately after write. A2:WSC -> 2260:w1p | O16: no
F17: presetn | G17: slv_des_mode_enable | H17: v | I17: 2 | J17: 2 | K17: 1 | L17: h0 | M17: rws | N17: when thrd_mode is 0, this bit is equivalent to des_mode_enable, sw needs to write 1 to start fetching cmd for slave thread | O17: no
F18: presetn | G18: low_power_enable | H18: v | I18: 3 | J18: 3 | K18: 1 | L18: h0 | M18: rw | N18: 0:disable clk gate 1:enable clk gate | O18: no(TBD)
F19: presetn | G19: des_clr | H19: v | I19: 4 | J19: 4 | K19: 1 | L19: h0 | M19: rws | N19: 清空指令buffer 写1‘b1 使能 自动清0 | O19: no
F20: presetn | G20: gif_bpn | I20: 5 | J20: 5 | K20: 1 | L20: h0 | M20: rw | N20: 为0时控制gif可反压，为1时gif不可反压 | O20: no
F21: presetn | G21: cache_cg_en | I21: 6 | J21: 6 | K21: 1 | L21: h0 | M21: rw | N21: 为1时 clk_gate tie1，为0时 clk_gate 根据指令控制 | O21: no
F22: presetn | G22: slv_sync_id_reset | H22: v | I22: 7 | J22: 7 | K22: 1 | L22: h0 | M22: w1p | N22: when thrd_mode = 0, this bit is used to set slave thread cmd_id to 32'h0 0: Do not reset the SyncID output 1: Reset the SyncID output to be all 0s This bit will be cleared immediately after write. A2:WSC -> 2260:w1p | O22: no
F23: presetn | G23: mst_ins_buf_status | H23: v | I23: 14 | J23: 8 | K23: 7 | L23: h40 | M23: ro | N23: master thread, Current entry number of the Ins Buf. It means how many descriptors that SW can write to Ins Buf. If the Ins Buf is full, this field will be 0. | O23: no
F24: presetn | G24: thrd_mode | H24: v | I24: 15 | J24: 15 | K24: 1 | L24: h0 | M24: rw | N24: sw set the dual thread mode. 0: sdma dual thread roundrobin; 1: gdma dual thread fork/join/exit | O24: no
F25: presetn | G25: slv_ins_buf_status | H25: v | I25: 31 | J25: 25 | K25: 7 | L25: h40 | M25: ro | N25: slave thread, Current entry number of the Ins Buf. It means how many descriptors that SW can write to Ins Buf. If the Ins Buf is full, this field will be 0. | O25: no
A26: h4 | B26: h4 | C26: gdma_csr_1 | F26: presetn | G26: master_des_addr_l32 | H26: v | I26: 31 | J26: 0 | K26: 32 | L26: h0 | M26: rw | N26: If the Ins Buf is full, this field will be 0. | O26: no
A27: h8 | B27: h8 | C27: gdma_csr_2 | F27: presetn | G27: master_des_addr_h1 | H27: v | I27: 0 | J27: 0 | K27: 1 | L27: h0 | M27: rw | N27: Master descriptor Address Pointer [39] is updated by this register’s bit. | O27: no
A28: hc | B28: hc | C28: gdma_csr_3 | F28: presetn | G28: slave_des_addr_l32 | H28: v | I28: 31 | J28: 0 | K28: 32 | L28: h0 | M28: rw | N28: Slave descriptor Address Pointer [38:7] is updated by this register’s bit. Slave descriptor address’s bit [6:0] are always 0. both SW and HW can write: add an ro type register for apb read path | O28: no
A29: h10 | B29: h10 | C29: gdma_csr_4 | F29: presetn | G29: slave_des_addr_h1 | H29: v | I29: 0 | J29: 0 | K29: 1 | L29: h0 | M29: rw | N29: Slave descriptor Address Pointer [39] is updated by this register’s bit. | O29: no
A30: h14 | B30: h14 | C30: gdma_csr_5 | F30: presetn | G30: perf_monitor_res_start_addr_l32 | I30: 31 | J30: 0 | K30: 32 | L30: h0 | M30: rw | N30: the ddr start address [38:7] for performance monitor is update by this register's bit[31:0].bit[0]must be 0 the bit [6:0] is always 0.
A31: h18 | B31: h18 | C31: gdma_csr_6 | F31: presetn | G31: perf_monitor_res_start_addr_h1 | I31: 0 | J31: 0 | K31: 1 | L31: h0 | M31: rw | N31: the ddr start address [39] for performance monitor is update by this register's bit[0].
A32: h1c | B32: h1c | C32: gdma_csr_7 | F32: presetn | G32: perf_monitor_res_end_addr_l32 | I32: 31 | J32: 0 | K32: 32 | L32: h0 | M32: rw | N32: the ddr end address [38:7] for performance monitor is update by this register's bit[31:0].bit[0] must be 0 the bit [6:0] is always 0.
A33: h20 | B33: h20 | C33: gdma_csr_8 | F33: presetn | G33: perf_monitor_res_end_addr_h1 | I33: 0 | J33: 0 | K33: 1 | L33: h0 | M33: rw | N33: the ddr end address [39] for performance monitor is update by this register's bit[0].
A34: h24 | B34: h24 | C34: gdma_csr_9 | F34: presetn | G34: mst_current_sync_id | H34: v | I34: 31 | J34: 0 | K34: 32 | L34: h0 | M34: ro | N34: Current SyncID output of this engine. This field will automatically update to be consistent with the SyncID output of this engine for master thread. | O34: no
A35: h28 | B35: h28 | C35: gdma_csr_10 | F35: presetn | G35: word_nums_after_filter | I35: 31 | J35: 0 | K35: 32 | L35: h0 | M35: rwc | N35: used in DMA_masked_select/DMA_nonzero command, this means the number of the data after filtering . A2:WTC(address decoded clear) -> 2260:rwc(write 1 to clear) | O35: no
A36: h2c | B36: h2c | C36: gdma_csr_11 | F36: presetn | G36: mem_size_per_npu | I36: 0 | J36: 0 | K36: 1 | L36: h1 | M36: ro | N36: For NCHW data, based on MEM size of a NPU, it can know the start address of next NPU 0: 128KB 1: 256KB | O36: no
F37: presetn | G37: eu_num_per_npu | I37: 1 | J37: 1 | K37: 1 | L37: h0 | M37: ro | N37: EU_NUM in each NPU (operate on int8) 0: 128; | O37: no
F38: presetn | G38: npu_num | I38: 2 | J38: 2 | K38: 1 | L38: h0 | M38: ro | N38: NPU NUMBER 0: 64; 1: 32； | O38: no
A39: h30 | B39: h30 | C39: gdma_csr_12 | F39: presetn | G39: intr_status_disable | I39: 0 | J39: 0 | K39: 1 | L39: h1 | M39: rw | N39: Interrupt Disable,highest priority in interrupt generation (gdma/sdma) 0: Enable all interrupt (其它 gdma_csr_12 的 intr_*_disable 可以起作用) 1: Disable all interrupt (关闭所有 function 中断产生，其它 gdma_csr_12 的 intr_*_disable 不起作用) When this bit is cleared, the interrupt generation is decided by each individual interrupt enable bits. | O39: no
F40: presetn | G40: intr_des_mode_end_disable | I40: 1 | J40: 1 | K40: 1 | L40: h0 | M40: rw | N40: 主线程 chain_end sys 指令执行完成中断无效 (gdma/sdma) 0: interrupt generation is enabled 1: interrupt is masked (不产生该中断) | O40: no
...

Sheet DMA_tensor（0x000）
A1: Field | B1: Length（bit） | C1: High （bit） | D1: Low （bit） | E1: SW Offset address | F1: SW High(bit) | G1: SW Low（bit） | H1: RW | I1: descriptions | J1: configure_necessery
A2: intr_en | B2: 1 | C2: =D2+B2-1 -> 0 | D2: 0 | E2: =ROUNDDOWN(C2/32,0) -> 0 | F2: =C2-E2*32 -> 0 | G2: =D2-E2*32 -> 0 | H2: RW | I2: =CONCATENATE(INDIRECT("template!I2")) -> Interrupt Enable;if this bit is set, CPU COULD get interrupt when the instruction is finished 0: disable interrupt 1: enable interrupt | J2: ASITIS | L2: 由软件配置
A3: stride_enable | B3: 1 | C3: =D3+B3-1 -> 1 | D3: =INDIRECT(ADDRESS(ROW()-1,COLUMN()-1))+1 -> 1 | E3: =ROUNDDOWN(C3/32,0) -> 0 | F3: =C3-E3*32 -> 1 | G3: =D3-E3*32 -> 1 | H3: RW | I3: =CONCATENATE(INDIRECT("template!I3")) -> Stride enable 0：No stride for all blob definition 1：Enable stride for all blob definition | J3: ASITIS | L3: 无需软件配置，且不影响硬件行为的field
A4: nchw_copy | B4: 1 | C4: =D4+B4-1 -> 2 | D4: =INDIRECT(ADDRESS(ROW()-1,COLUMN()-1))+1 -> 2 | E4: =ROUNDDOWN(C4/32,0) -> 0 | F4: =C4-E4*32 -> 2 | G4: =D4-E4*32 -> 2 | H4: RW | I4: =CONCATENATE(INDIRECT("template!I4")) -> NCHW copy bit 0: use separate src and dst NCHW value setting 1: reuse src NCHW value for dst NCHW value | J4: ASITIS | L4: 无需软件配置，由硬件推导的配置
A5: cmd_short | B5: 1 | C5: =D5+B5-1 -> 3 | D5: =INDIRECT(ADDRESS(ROW()-1,COLUMN()-1))+1 -> 3 | E5: =ROUNDDOWN(C5/32,0) -> 0 | F5: =C5-E5*32 -> 3 | G5: =D5-E5*32 -> 3 | H5: RW | I5: =CONCATENATE(INDIRECT("template!I5")) -> 0:768bit full cmd; 1:128/256/384/512 short cmd | J5: ASITIS
A6: cache_en | B6: 1 | C6: =D6+B6-1 -> 4 | D6: =INDIRECT(ADDRESS(ROW()-1,COLUMN()-1))+1 -> 4 | E6: =ROUNDDOWN(C6/32,0) -> 0 | F6: =C6-E6*32 -> 4 | G6: =D6-E6*32 -> 4 | H6: RW | I6: =CONCATENATE(INDIRECT("template!I6")) -> Read cache enable 0: Read not use cache 1: Read use cache | J6: ASITIS
A7: cache_flush | B7: 1 | C7: =D7+B7-1 -> 5 | D7: =INDIRECT(ADDRESS(ROW()-1,COLUMN()-1))+1 -> 5 | E7: =ROUNDDOWN(C7/32,0) -> 0 | F7: =C7-E7*32 -> 5 | G7: =D7-E7*32 -> 5 | H7: RW | I7: =CONCATENATE(INDIRECT("template!I7")) -> Flush cache 0: Not Flush cache 1: Flush cache | J7: ASITIS
A8: reserved | B8: 2 | C8: =D8+B8-1 -> 7 | D8: =INDIRECT(ADDRESS(ROW()-1,COLUMN()-1))+1 -> 6 | E8: =ROUNDDOWN(C8/32,0) -> 0 | F8: =C8-E8*32 -> 7 | G8: =D8-E8*32 -> 6 | H8: RO | I8: =CONCATENATE(INDIRECT("template!I8")) -> reserved | J8: 0
A9: bid_in_order | B9: 1 | C9: =D9+B9-1 -> 8 | D9: 8 | E9: 0 | F9: 8 | G9: 8 | H9: RW | J9: ASITIS
A10: bw_lmt_rd | B10: 1 | C10: =D10+B10-1 -> 9 | D10: 9 | E10: 0 | F10: 9 | G10: 9 | H10: RW | J10: ASITIS
A11: bw_lmt_wr | B11: 1 | C11: =D11+B11-1 -> 10 | D11: 10 | E11: 0 | F11: 10 | G11: 10 | H11: RW | J11: ASITIS
A12: early_resp_dis | B12: 1 | C12: 11 | D12: 11 | E12: 0 | F12: 11 | G12: 11 | H12: RW | J12: ASITIS
A13: Reserved | B13: 20 | C13: =D13+B13-1 -> 31 | D13: =INDIRECT(ADDRESS(ROW()-1,COLUMN()-1))+1 -> 12 | E13: =ROUNDDOWN(C13/32,0) -> 0 | F13: =C13-E13*32 -> 31 | G13: =D13-E13*32 -> 12 | H13: RO | I13: =CONCATENATE(INDIRECT("template!I9")) | J13: 0
A14: cmd_type | B14: 5 | C14: =D14+B14-1 -> 36 | D14: =INDIRECT(ADDRESS(ROW()-1,COLUMN()-1))+1 -> 32 | E14: =ROUNDDOWN(C14/32,0) -> 1 | F14: =C14-E14*32 -> 4 | G14: =D14-E14*32 -> 0 | H14: RW | I14: =CONCATENATE(INDIRECT("template!I14")) -> 0x0:GDMA_tensor 0x1:GDMA_matrix 0x2:GDMA_masked_select 0x3:GDMA_general 0x5:GDMA_nonzero 0x6:GDMA_sys 0x7:GDMA_gather 0x8:GDMA_scatter 0x9:GDMA_reverse 0xc:GDMA_lossy_compress 0xd:GDMA_lossy_decompress | J14: ASITIS
A15: cmd_special_function | B15: 3 | C15: =D15+B15-1 -> 39 | D15: =INDIRECT(ADDRESS(ROW()-1,COLUMN()-1))+1 -> 37 | E15: =ROUNDDOWN(C15/32,0) -> 1 | F15: =C15-E15*32 -> 7 | G15: =D15-E15*32 -> 5 | H15: RW | I15: =CONCATENATE(INDIRECT("template!I15")) -> this field is connected with cmd_type. when cmd_type == DMA_tensor 000: No special function 001: Enable transposition write (For Neuron transposition case, the dest_N= src_C, dest_C=src_N) 011: broadcast：only support C size<=64 and lmem mask invalid others: reserved | J15: ASITIS
A16: fill_constant_en | B16: 1 | C16: =D16+B16-1 -> 40 | D16: =INDIRECT(ADDRESS(ROW()-1,COLUMN()-1))+1 -> 40 | E16: =ROUNDDOWN(C16/32,0) -> 1 | F16: =C16-E16*32 -> 8 | G16: =D16-E16*32 -> 8 | H16: RW | I16: 0: no fill constant 1: fill constant enable only support special_func=000/011/100 | J16: ASITIS
A17: src_data_format | B17: 4 | C17: =D17+B17-1 -> 44 | D17: =INDIRECT(ADDRESS(ROW()-1,COLUMN()-1))+1 -> 41 | E17: =ROUNDDOWN(C17/32,0) -> 1 | F17: =C17-E17*32 -> 12 | G17: =D17-E17*32 -> 9 | H17: RW | I17: =CONCATENATE(INDIRECT("template!I17")) -> Source Data Format 0:INT8 1:FP16 2:FP32 3:INT16 4:INT32 5:BFP16 6:FP20 7:FP8 E4M3 8:FP8 E5M2 others：not support | J17: ASITIS
A18: reserved | B18: 3 | C18: =D18+B18-1 -> 47 | D18: =INDIRECT(ADDRESS(ROW()-1,COLUMN()-1))+1 -> 45 | E18: =ROUNDDOWN(C18/32,0) -> 1 | F18: =C18-E18*32 -> 15 | G18: =D18-E18*32 -> 13 | H18: RO | I18: =CONCATENATE(INDIRECT("template!I18")) -> reserved | J18: 0
A19: reserved | B19: 16 | C19: =D19+B19-1 -> 63 | D19: =INDIRECT(ADDRESS(ROW()-1,COLUMN()-1))+1 -> 48 | E19: =ROUNDDOWN(C19/32,0) -> 1 | F19: =C19-E19*32 -> 31 | G19: =D19-E19*32 -> 16 | H19: RO | I19: reserved (for CDMA src_hsize[31:16], GDMA must tie 0) | J19: 0
A20: cmd_id_dep | B20: 21 | C20: =D20+B20-1 -> 84 | D20: =INDIRECT(ADDRESS(ROW()-1,COLUMN()-1))+1 -> 64 | E20: =ROUNDDOWN(C20/32,0) -> 2 | F20: =C20-E20*32 -> 20 | G20: =D20-E20*32 -> 0 | H20: RW | I20: Execution of this descriptor need to wait for engine[i]'s cmd_id which depends on the cmd_id_en to be bigger than the ID specified in this field. [19:0] is depend_id, [20] is depend_id_enable(0:disable; 1:enable) | J20: ASITIS
A21: reserved | B21: 2 | C21: 86 | D21: 85 | E21: =ROUNDDOWN(C21/32,0) -> 2 | F21: 22 | G21: =D21-E21*32 -> 21 | H21: RO | I21: reserved
A22: break_point | B22: 1 | C22: 87 | D22: 87 | E22: 2 | F22: 23 | G22: 23 | H22: RW | I22: when dbg_mode equals to 2'b10 and this bit is 1, the gdma will stop executing the next descriptor after this descriptor is executed,
A23: reserved | B23: 8 | C23: =D23+B23-1 -> 95 | D23: =INDIRECT(ADDRESS(ROW()-1,COLUMN()-1))+1 -> 88 | E23: =ROUNDDOWN(C23/32,0) -> 2 | F23: 31 | G23: =D23-E23*32 -> 24 | H23: RO | I23: reserved
A24: constant_value | B24: 32 | C24: =D24+B24-1 -> 127 | D24: =INDIRECT(ADDRESS(ROW()-1,COLUMN()-1))+1 -> 96 | E24: =ROUNDDOWN(C24/32,0) -> 3 | F24: =C24-E24*32 -> 31 | G24: =D24-E24*32 -> 0 | H24: RW | I24: =CONCATENATE(INDIRECT("template!I24")) -> when cmd_special_function==fill constant, this field means constant value | J24: fill constant:ASITIS others:0
A25: src_nstride | B25: 32 | C25: =D25+B25-1 -> 159 | D25: =INDIRECT(ADDRESS(ROW()-1,COLUMN()-1))+1 -> 128 | E25: =ROUNDDOWN(C25/32,0) -> 4 | F25: =C25-E25*32 -> 31 | G25: =D25-E25*32 -> 0 | H25: RW | I25: =CONCATENATE(INDIRECT("template!I25")) -> unsigned number; Source blob N stride | J25: fill constant:no need to config others:ASITIS
A26: src_cstride | B26: 32 | C26: =D26+B26-1 -> 191 | D26: =INDIRECT(ADDRESS(ROW()-1,COLUMN()-1))+1 -> 160 | E26: =ROUNDDOWN(C26/32,0) -> 5 | F26: =C26-E26*32 -> 31 | G26: =D26-E26*32 -> 0 | H26: RW | I26: =CONCATENATE(INDIRECT("template!I26")) -> unsigned number. Source blob C stride | J26: fill constant:no need to config broadcast:no need to config lmem 4 bank broadcast:no need to config others:ASITIS
A27: src_hstride | B27: 32 | C27: =D27+B27-1 -> 223 | D27: =INDIRECT(ADDRESS(ROW()-1,COLUMN()-1))+1 -> 192 | E27: =ROUNDDOWN(C27/32,0) -> 6 | F27: =C27-E27*32 -> 31 | G27: =D27-E27*32 -> 0 | H27: RW | I27: =CONCATENATE(INDIRECT("template!I27")) -> unsigned number; Source blob H stride | J27: fill constant:no need to config others:ASITIS
A28: src_wstride | B28: 32 | C28: =D28+B28-1 -> 255 | D28: =INDIRECT(ADDRESS(ROW()-1,COLUMN()-1))+1 -> 224 | E28: =ROUNDDOWN(C28/32,0) -> 7 | F28: =C28-E28*32 -> 31 | G28: =D28-E28*32 -> 0 | H28: RW | I28: =CONCATENATE(INDIRECT("template!I28")) -> unsigned number; Source blob W stride | J28: spfunc=000:ASITIS others:no need to config
A29: dst_nstride | B29: 32 | C29: =D29+B29-1 -> 287 | D29: =INDIRECT(ADDRESS(ROW()-1,COLUMN()-1))+1 -> 256 | E29: =ROUNDDOWN(C29/32,0) -> 8 | F29: =C29-E29*32 -> 31 | G29: =D29-E29*32 -> 0 | H29: RW | I29: =CONCATENATE(INDIRECT("template!I29")) -> unsigned number; desitination blob N stride | J29: ASITIS
A30: dst_cstride | B30: 32 | C30: =D30+B30-1 -> 319 | D30: =INDIRECT(ADDRESS(ROW()-1,COLUMN()-1))+1 -> 288 | E30: =ROUNDDOWN(C30/32,0) -> 9 | F30: =C30-E30*32 -> 31 | G30: =D30-E30*32 -> 0 | H30: RW | I30: =CONCATENATE(INDIRECT("template!I30")) -> unsigned number.desitination blob C stride | J30: ASITIS
A31: dst_hstride | B31: 32 | C31: =D31+B31-1 -> 351 | D31: =INDIRECT(ADDRESS(ROW()-1,COLUMN()-1))+1 -> 320 | E31: =ROUNDDOWN(C31/32,0) -> 10 | F31: =C31-E31*32 -> 31 | G31: =D31-E31*32 -> 0 | H31: RW | I31: =CONCATENATE(INDIRECT("template!I31")) -> unsigned number; desitination blob H stride | J31: ASITIS
A32: dst_wstride | B32: 32 | C32: =D32+B32-1 -> 383 | D32: =INDIRECT(ADDRESS(ROW()-1,COLUMN()-1))+1 -> 352 | E32: =ROUNDDOWN(C32/32,0) -> 11 | F32: =C32-E32*32 -> 31 | G32: =D32-E32*32 -> 0 | H32: RW | I32: =INDIRECT("template!I32") -> unsigned number; desitination blob W stride | J32: spfunc=000:ASITIS others:no need to config
A33: src_nsize | B33: 16 | C33: =D33+B33-1 -> 399 | D33: =INDIRECT(ADDRESS(ROW()-1,COLUMN()-1))+1 -> 384 | E33: =ROUNDDOWN(C33/32,0) -> 12 | F33: =C33-E33*32 -> 15 | G33: =D33-E33*32 -> 0 | H33: RW | I33: =INDIRECT("template!I33") -> Source Blob Number | J33: fill constant:no need to config others:ASITIS
A34: src_csize | B34: 16 | C34: =D34+B34-1 -> 415 | D34: =INDIRECT(ADDRESS(ROW()-1,COLUMN()-1))+1 -> 400 | E34: =ROUNDDOWN(C34/32,0) -> 12 | F34: =C34-E34*32 -> 31 | G34: =D34-E34*32 -> 16 | H34: RW | I34: =INDIRECT("template!I34") -> Source blob C | J34: fill constant:no need to config broadcast:no need to config others:ASITIS
A35: src_hsize | B35: 16 | C35: =D35+B35-1 -> 431 | D35: =INDIRECT(ADDRESS(ROW()-1,COLUMN()-1))+1 -> 416 | E35: =ROUNDDOWN(C35/32,0) -> 13 | G35: =D35-E35*32 -> 0 | H35: RW | I35: =INDIRECT("template!I35") -> Source blob H | J35: fill constant:no need to config others:ASITIS
A36: src_wsize | B36: 16 | C36: =D36+B36-1 -> 447 | D36: =INDIRECT(ADDRESS(ROW()-1,COLUMN()-1))+1 -> 432 | E36: =ROUNDDOWN(C36/32,0) -> 13 | F36: =C36-E36*32 -> 31 | G36: =D36-E36*32 -> 16 | H36: RW | I36: =INDIRECT("template!I36") -> Source blob W | J36: fill constant:no need to config others:ASITIS
A37: dst_nsize | B37: 16 | C37: =D37+B37-1 -> 463 | D37: =INDIRECT(ADDRESS(ROW()-1,COLUMN()-1))+1 -> 448 | E37: =ROUNDDOWN(C37/32,0) -> 14 | F37: =C37-E37*32 -> 15 | G37: =D37-E37*32 -> 0 | H37: RW | I37: =INDIRECT("template!I37") -> Destination Blob Number | J37: NC_transpose: no need to config nchw_copy: no need to config others:ASITIS
A38: dst_csize | B38: 16 | C38: =D38+B38-1 -> 479 | D38: =INDIRECT(ADDRESS(ROW()-1,COLUMN()-1))+1 -> 464 | E38: =ROUNDDOWN(C38/32,0) -> 14 | F38: =C38-E38*32 -> 31 | G38: =D38-E38*32 -> 16 | H38: RW | I38: =INDIRECT("template!I38") -> Destination blob C | J38: NC_transpose: no need to config nchw_copy: no need to config others:ASITIS
A39: dst_hsize | B39: 16 | C39: =D39+B39-1 -> 495 | D39: =INDIRECT(ADDRESS(ROW()-1,COLUMN()-1))+1 -> 480 | E39: =ROUNDDOWN(C39/32,0) -> 15 | F39: =C39-E39*32 -> 15 | G39: =D39-E39*32 -> 0 | H39: RW | I39: =INDIRECT("template!I39") -> Destination blob H | J39: nchw_copy: no need to config ASITIS
A40: dst_wsize | B40: 16 | C40: =D40+B40-1 -> 511 | D40: =INDIRECT(ADDRESS(ROW()-1,COLUMN()-1))+1 -> 496 | E40: =ROUNDDOWN(C40/32,0) -> 15 | F40: =C40-E40*32 -> 31 | G40: =D40-E40*32 -> 16 | H40: RW | I40: =INDIRECT("template!I40") -> Destination blob W | J40: nchw_copy: no need to config ASITIS
...

Sheet DMA_matrix
A1: Field | B1: Length（bit） | C1: High （bit） | D1: Low （bit） | E1: SW Offset address | F1: SW High(bit) | G1: SW Low（bit） | H1: RW | I1: descriptions | J1: configure_necessery
A2: intr_en | B2: 1 | C2: =D2+B2-1 -> 0 | D2: 0 | E2: =ROUNDDOWN(C2/32,0) -> 0 | F2: =C2-E2*32 -> 0 | G2: =D2-E2*32 -> 0 | H2: RW | I2: =CONCATENATE(INDIRECT("template!I2")) -> Interrupt Enable;if this bit is set, CPU COULD get interrupt when the instruction is finished 0: disable interrupt 1: enable interrupt | J2: ASITIS
A3: stride_enable | B3: 1 | C3: =D3+B3-1 -> 1 | D3: =INDIRECT(ADDRESS(ROW()-1,COLUMN()-1))+1 -> 1 | E3: =ROUNDDOWN(C3/32,0) -> 0 | F3: =C3-E3*32 -> 1 | G3: =D3-E3*32 -> 1 | H3: RW | I3: =CONCATENATE(INDIRECT("template!I3")) -> Stride enable 0：No stride for all blob definition 1：Enable stride for all blob definition | J3: ASITIS
A4: nchw_copy | B4: 1 | C4: =D4+B4-1 -> 2 | D4: =INDIRECT(ADDRESS(ROW()-1,COLUMN()-1))+1 -> 2 | E4: =ROUNDDOWN(C4/32,0) -> 0 | F4: =C4-E4*32 -> 2 | G4: =D4-E4*32 -> 2 | H4: RW | I4: =CONCATENATE(INDIRECT("template!I4")) -> NCHW copy bit 0: use separate src and dst NCHW value setting 1: reuse src NCHW value for dst NCHW value | J4: 0
A5: cmd_short | B5: 1 | C5: =D5+B5-1 -> 3 | D5: =INDIRECT(ADDRESS(ROW()-1,COLUMN()-1))+1 -> 3 | E5: =ROUNDDOWN(C5/32,0) -> 0 | F5: =C5-E5*32 -> 3 | G5: =D5-E5*32 -> 3 | H5: RW | I5: =CONCATENATE(INDIRECT("template!I5")) -> 0:768bit full cmd; 1:128/256/384/512 short cmd | J5: ASITIS
A6: cache_en | B6: 1 | C6: =D6+B6-1 -> 4 | D6: =INDIRECT(ADDRESS(ROW()-1,COLUMN()-1))+1 -> 4 | E6: =ROUNDDOWN(C6/32,0) -> 0 | F6: =C6-E6*32 -> 4 | G6: =D6-E6*32 -> 4 | H6: RW | I6: =CONCATENATE(INDIRECT("template!I6")) -> Read cache enable 0: Read not use cache 1: Read use cache | J6: ASITIS
A7: cache_flush | B7: 1 | C7: =D7+B7-1 -> 5 | D7: =INDIRECT(ADDRESS(ROW()-1,COLUMN()-1))+1 -> 5 | E7: =ROUNDDOWN(C7/32,0) -> 0 | F7: =C7-E7*32 -> 5 | G7: =D7-E7*32 -> 5 | H7: RW | I7: =CONCATENATE(INDIRECT("template!I7")) -> Flush cache 0: Not Flush cache 1: Flush cache | J7: ASITIS
A8: reserved | B8: 2 | C8: =D8+B8-1 -> 7 | D8: =INDIRECT(ADDRESS(ROW()-1,COLUMN()-1))+1 -> 6 | E8: =ROUNDDOWN(C8/32,0) -> 0 | F8: =C8-E8*32 -> 7 | G8: =D8-E8*32 -> 6 | H8: RO | I8: =CONCATENATE(INDIRECT("template!I8")) -> reserved | J8: 0
A9: bid_in_order | B9: 1 | C9: =D9+B9-1 -> 8 | D9: 8 | E9: 0 | F9: 8 | G9: 8 | H9: RW | J9: ASITIS
A10: bw_lmt_rd | B10: 1 | C10: =D10+B10-1 -> 9 | D10: 9 | E10: 0 | F10: 9 | G10: 9 | H10: RW | J10: ASITIS
A11: bw_lmt_wr | B11: 1 | C11: =D11+B11-1 -> 10 | D11: 10 | E11: 0 | F11: 10 | G11: 10 | H11: RW | J11: ASITIS
A12: early_resp_dis | B12: 1 | C12: 11 | D12: 11 | E12: 0 | F12: 11 | G12: 11 | H12: RW | J12: ASITIS
A13: Reserved | B13: 20 | C13: =D13+B13-1 -> 31 | D13: =INDIRECT(ADDRESS(ROW()-1,COLUMN()-1))+1 -> 12 | E13: =ROUNDDOWN(C13/32,0) -> 0 | F13: =C13-E13*32 -> 31 | G13: =D13-E13*32 -> 12 | H13: RO | I13: =CONCATENATE(INDIRECT("template!I9")) | J13: 0
A14: cmd_type | B14: 5 | C14: =D14+B14-1 -> 36 | D14: =INDIRECT(ADDRESS(ROW()-1,COLUMN()-1))+1 -> 32 | E14: =ROUNDDOWN(C14/32,0) -> 1 | F14: =C14-E14*32 -> 4 | G14: =D14-E14*32 -> 0 | H14: RW | I14: =CONCATENATE(INDIRECT("template!I14")) -> 0x0:GDMA_tensor 0x1:GDMA_matrix 0x2:GDMA_masked_select 0x3:GDMA_general 0x5:GDMA_nonzero 0x6:GDMA_sys 0x7:GDMA_gather 0x8:GDMA_scatter 0x9:GDMA_reverse 0xc:GDMA_lossy_compress 0xd:GDMA_lossy_decompress | J14: ASITIS
A15: cmd_special_function | B15: 3 | C15: =D15+B15-1 -> 39 | D15: =INDIRECT(ADDRESS(ROW()-1,COLUMN()-1))+1 -> 37 | E15: =ROUNDDOWN(C15/32,0) -> 1 | F15: =C15-E15*32 -> 7 | G15: =D15-E15*32 -> 5 | H15: RW | I15: this field is connected with cmd_type. when cmd_type == DMA_matrix 0000: no special function,which means A(h,c,0,w)=B(0,0,h,c*w) 0001: matrix transpose,which means A(h,c,0,w)=B(0,0,c*w,h) others: reserved | J15: ASITIS
A16: fill_constant_en | B16: 1 | C16: =D16+B16-1 -> 40 | D16: =INDIRECT(ADDRESS(ROW()-1,COLUMN()-1))+1 -> 40 | E16: =ROUNDDOWN(C16/32,0) -> 1 | F16: =C16-E16*32 -> 8 | G16: =D16-E16*32 -> 8 | H16: RW | I16: 0: no fill constant | J16: no need to config
A17: src_data_format | B17: 4 | C17: =D17+B17-1 -> 44 | D17: =INDIRECT(ADDRESS(ROW()-1,COLUMN()-1))+1 -> 41 | E17: =ROUNDDOWN(C17/32,0) -> 1 | F17: =C17-E17*32 -> 12 | G17: =D17-E17*32 -> 9 | H17: RW | I17: Source Data Format 0:INT8 1:FP16 2:FP32 3:INT16 4:INT32 5:BFP16 7:FP8 E4M3 8:FP8 E5M2 others：not support | J17: ASITIS
A18: reserved | B18: 19 | C18: =D18+B18-1 -> 63 | D18: =INDIRECT(ADDRESS(ROW()-1,COLUMN()-1))+1 -> 45 | E18: =ROUNDDOWN(C18/32,0) -> 1 | F18: =C18-E18*32 -> 31 | G18: =D18-E18*32 -> 13 | H18: RO | I18: =CONCATENATE(INDIRECT("template!I18")) -> reserved | J18: 0
A19: cmd_id_dep | B19: 21 | C19: =D19+B19-1 -> 84 | D19: =INDIRECT(ADDRESS(ROW()-1,COLUMN()-1))+1 -> 64 | E19: =ROUNDDOWN(C19/32,0) -> 2 | F19: =C19-E19*32 -> 20 | G19: =D19-E19*32 -> 0 | H19: RW | I19: Execution of this descriptor need to wait for engine[i]'s cmd_id which depends on the cmd_id_en to be bigger than the ID specified in this field. [19:0] is depend_id, [20] is depend_id_enable(0:disable; 1:enable) | J19: ASITIS
A20: reserved | B20: 2 | C20: 86 | D20: 85 | E20: =ROUNDDOWN(C20/32,0) -> 2 | F20: 22 | G20: =D20-E20*32 -> 21 | H20: RO | I20: reserved
A21: break_point | B21: 1 | C21: 87 | D21: 87 | E21: 2 | F21: 23 | G21: 23 | H21: RW | I21: when dbg_mode equals to 2'b10 and this bit is 1, the gdma will stop executing the next descriptor after this descriptor is executed,
A22: reserved | B22: 8 | C22: =D22+B22-1 -> 95 | D22: =INDIRECT(ADDRESS(ROW()-1,COLUMN()-1))+1 -> 88 | E22: =ROUNDDOWN(C22/32,0) -> 2 | F22: 31 | G22: =D22-E22*32 -> 24 | H22: RO | I22: reserved
A23: constant_value | B23: 32 | C23: =D23+B23-1 -> 127 | D23: =INDIRECT(ADDRESS(ROW()-1,COLUMN()-1))+1 -> 96 | E23: =ROUNDDOWN(C23/32,0) -> 3 | F23: =C23-E23*32 -> 31 | G23: =D23-E23*32 -> 0 | H23: RW | I23: =CONCATENATE(INDIRECT("template!I24")) -> when cmd_special_function==fill constant, this field means constant value | J23: 0
A24: src_nstride | B24: 32 | C24: =D24+B24-1 -> 159 | D24: =INDIRECT(ADDRESS(ROW()-1,COLUMN()-1))+1 -> 128 | E24: =ROUNDDOWN(C24/32,0) -> 4 | F24: =C24-E24*32 -> 31 | G24: =D24-E24*32 -> 0 | H24: RW | I24: =CONCATENATE(INDIRECT("template!I25")) -> unsigned number; Source blob N stride | J24: src is lmem : ASITIS others: no need to config
A25: src_cstride | B25: 32 | C25: =D25+B25-1 -> 191 | D25: =INDIRECT(ADDRESS(ROW()-1,COLUMN()-1))+1 -> 160 | E25: =ROUNDDOWN(C25/32,0) -> 5 | F25: =C25-E25*32 -> 31 | G25: =D25-E25*32 -> 0 | H25: RW | I25: =CONCATENATE(INDIRECT("template!I26")) -> unsigned number. Source blob C stride | J25: src is lmem : ASITIS others: no need to config
A26: src_hstride | B26: 32 | C26: =D26+B26-1 -> 223 | D26: =INDIRECT(ADDRESS(ROW()-1,COLUMN()-1))+1 -> 192 | E26: =ROUNDDOWN(C26/32,0) -> 6 | F26: =C26-E26*32 -> 31 | G26: =D26-E26*32 -> 0 | H26: RW | I26: =CONCATENATE(INDIRECT("template!I27")) -> unsigned number; Source blob H stride | J26: src is lmem : no need to config others: ASITIS
A27: src_wstride | B27: 32 | C27: =D27+B27-1 -> 255 | D27: =INDIRECT(ADDRESS(ROW()-1,COLUMN()-1))+1 -> 224 | E27: =ROUNDDOWN(C27/32,0) -> 7 | F27: =C27-E27*32 -> 31 | G27: =D27-E27*32 -> 0 | H27: RW | I27: =CONCATENATE(INDIRECT("template!I28")) -> unsigned number; Source blob W stride | J27: no need to config
A28: dst_nstride | B28: 32 | C28: =D28+B28-1 -> 287 | D28: =INDIRECT(ADDRESS(ROW()-1,COLUMN()-1))+1 -> 256 | E28: =ROUNDDOWN(C28/32,0) -> 8 | F28: =C28-E28*32 -> 31 | G28: =D28-E28*32 -> 0 | H28: RW | I28: =CONCATENATE(INDIRECT("template!I29")) -> unsigned number; desitination blob N stride | J28: src is lmem : no need to config others: ASITIS
A29: dst_cstride | B29: 32 | C29: =D29+B29-1 -> 319 | D29: =INDIRECT(ADDRESS(ROW()-1,COLUMN()-1))+1 -> 288 | E29: =ROUNDDOWN(C29/32,0) -> 9 | F29: =C29-E29*32 -> 31 | G29: =D29-E29*32 -> 0 | H29: RW | I29: =CONCATENATE(INDIRECT("template!I30")) -> unsigned number.desitination blob C stride | J29: src is lmem : no need to config others: ASITIS
A30: dst_hstride | B30: 32 | C30: =D30+B30-1 -> 351 | D30: =INDIRECT(ADDRESS(ROW()-1,COLUMN()-1))+1 -> 320 | E30: =ROUNDDOWN(C30/32,0) -> 10 | F30: =C30-E30*32 -> 31 | G30: =D30-E30*32 -> 0 | H30: RW | I30: =CONCATENATE(INDIRECT("template!I31")) -> unsigned number; desitination blob H stride | J30: src is lmem : ASITIS others: no need to config
A31: dst_wstride | B31: 32 | C31: =D31+B31-1 -> 383 | D31: =INDIRECT(ADDRESS(ROW()-1,COLUMN()-1))+1 -> 352 | E31: =ROUNDDOWN(C31/32,0) -> 11 | F31: =C31-E31*32 -> 31 | G31: =D31-E31*32 -> 0 | H31: RW | I31: =INDIRECT("template!I32") -> unsigned number; desitination blob W stride | J31: no need to config
A32: src_nsize | B32: 16 | C32: =D32+B32-1 -> 399 | D32: =INDIRECT(ADDRESS(ROW()-1,COLUMN()-1))+1 -> 384 | E32: =ROUNDDOWN(C32/32,0) -> 12 | F32: =C32-E32*32 -> 15 | G32: =D32-E32*32 -> 0 | H32: RW | I32: =INDIRECT("template!I33") -> Source Blob Number | J32: src is lmem : ASITIS others: no need to config
A33: src_csize | B33: 16 | C33: =D33+B33-1 -> 415 | D33: =INDIRECT(ADDRESS(ROW()-1,COLUMN()-1))+1 -> 400 | E33: =ROUNDDOWN(C33/32,0) -> 12 | F33: =C33-E33*32 -> 31 | G33: =D33-E33*32 -> 16 | H33: RW | I33: =INDIRECT("template!I34") -> Source blob C | J33: src is lmem : ASITIS others: no need to config
A34: src_hsize | B34: 16 | C34: =D34+B34-1 -> 431 | D34: =INDIRECT(ADDRESS(ROW()-1,COLUMN()-1))+1 -> 416 | E34: =ROUNDDOWN(C34/32,0) -> 13 | F34: =C34-E34*32 -> 15 | G34: =D34-E34*32 -> 0 | H34: RW | I34: =INDIRECT("template!I35") -> Source blob H | J34: src is lmem : no need to config others: ASITIS
A35: src_wsize | B35: 16 | C35: =D35+B35-1 -> 447 | D35: =INDIRECT(ADDRESS(ROW()-1,COLUMN()-1))+1 -> 432 | E35: =ROUNDDOWN(C35/32,0) -> 13 | F35: =C35-E35*32 -> 31 | G35: =D35-E35*32 -> 16 | H35: RW | I35: =INDIRECT("template!I36") -> Source blob W | J35: ASITIS
A36: dst_nsize | B36: 16 | C36: =D36+B36-1 -> 463 | D36: =INDIRECT(ADDRESS(ROW()-1,COLUMN()-1))+1 -> 448 | E36: =ROUNDDOWN(C36/32,0) -> 14 | F36: =C36-E36*32 -> 15 | G36: =D36-E36*32 -> 0 | H36: RW | I36: =INDIRECT("template!I37") -> Destination Blob Number | J36: no need to config
A37: dst_csize | B37: 16 | C37: =D37+B37-1 -> 479 | D37: =INDIRECT(ADDRESS(ROW()-1,COLUMN()-1))+1 -> 464 | E37: =ROUNDDOWN(C37/32,0) -> 14 | F37: =C37-E37*32 -> 31 | G37: =D37-E37*32 -> 16 | H37: RW | I37: =INDIRECT("template!I38") -> Destination blob C | J37: src is lmem : no need to config others: ASITIS
A38: dst_hsize | B38: 16 | C38: =D38+B38-1 -> 495 | D38: =INDIRECT(ADDRESS(ROW()-1,COLUMN()-1))+1 -> 480 | E38: =ROUNDDOWN(C38/32,0) -> 15 | F38: =C38-E38*32 -> 15 | G38: =D38-E38*32 -> 0 | H38: RW | I38: =INDIRECT("template!I39") -> Destination blob H | J38: src is lmem : ASITIS others: no need to config
A39: dst_wsize | B39: 16 | C39: =D39+B39-1 -> 511 | D39: =INDIRECT(ADDRESS(ROW()-1,COLUMN()-1))+1 -> 496 | E39: =ROUNDDOWN(C39/32,0) -> 15 | F39: =C39-E39*32 -> 31 | G39: =D39-E39*32 -> 16 | H39: RW | I39: =INDIRECT("template!I40") -> Destination blob W | J39: ASITIS
A40: src_start_addr_l32 | B40: 32 | C40: =D40+B40-1 -> 543 | D40: =INDIRECT(ADDRESS(ROW()-1,COLUMN()-1))+1 -> 512 | E40: =ROUNDDOWN(C40/32,0) -> 16 | F40: =C40-E40*32 -> 31 | G40: =D40-E40*32 -> 0 | H40: RW | I40: =INDIRECT("template!I41") -> source blob start address[31:0] | J40: ASITIS
...

Sheet sDMA_matrix
A1: Field | B1: Length（bit） | C1: High （bit） | D1: Low （bit） | E1: SW Offset address | F1: SW High(bit) | G1: SW Low（bit） | H1: RW | I1: descriptions | J1: configure_necessery
A2: intr_en | B2: 1 | C2: =D2+B2-1 -> 0 | D2: 0 | E2: =ROUNDDOWN(C2/32,0) -> 0 | F2: =C2-E2*32 -> 0 | G2: =D2-E2*32 -> 0 | H2: RW | I2: =CONCATENATE(INDIRECT("template!I2")) -> Interrupt Enable;if this bit is set, CPU COULD get interrupt when the instruction is finished 0: disable interrupt 1: enable interrupt | J2: ASITIS
A3: stride_enable | B3: 1 | C3: =D3+B3-1 -> 1 | D3: =INDIRECT(ADDRESS(ROW()-1,COLUMN()-1))+1 -> 1 | E3: =ROUNDDOWN(C3/32,0) -> 0 | F3: =C3-E3*32 -> 1 | G3: =D3-E3*32 -> 1 | H3: RW | I3: =CONCATENATE(INDIRECT("template!I3")) -> Stride enable 0：No stride for all blob definition 1：Enable stride for all blob definition | J3: ASITIS
A4: nchw_copy | B4: 1 | C4: =D4+B4-1 -> 2 | D4: =INDIRECT(ADDRESS(ROW()-1,COLUMN()-1))+1 -> 2 | E4: =ROUNDDOWN(C4/32,0) -> 0 | F4: =C4-E4*32 -> 2 | G4: =D4-E4*32 -> 2 | H4: RW | I4: =CONCATENATE(INDIRECT("template!I4")) -> NCHW copy bit 0: use separate src and dst NCHW value setting 1: reuse src NCHW value for dst NCHW value | J4: 0
A5: cmd_short | B5: 1 | C5: =D5+B5-1 -> 3 | D5: =INDIRECT(ADDRESS(ROW()-1,COLUMN()-1))+1 -> 3 | E5: =ROUNDDOWN(C5/32,0) -> 0 | F5: =C5-E5*32 -> 3 | G5: =D5-E5*32 -> 3 | H5: RW | I5: =CONCATENATE(INDIRECT("template!I5")) -> 0:768bit full cmd; 1:128/256/384/512 short cmd | J5: ASITIS
A6: reserved | B6: 1 | C6: =D6+B6-1 -> 4 | D6: =INDIRECT(ADDRESS(ROW()-1,COLUMN()-1))+1 -> 4 | E6: =ROUNDDOWN(C6/32,0) -> 0 | F6: =C6-E6*32 -> 4 | G6: =D6-E6*32 -> 4 | H6: RO | I6: =CONCATENATE(INDIRECT("template!I6")) -> Read cache enable 0: Read not use cache 1: Read use cache | J6: 0
A7: reserved | B7: 4 | C7: =D7+B7-1 -> 8 | D7: =INDIRECT(ADDRESS(ROW()-1,COLUMN()-1))+1 -> 5 | E7: =ROUNDDOWN(C7/32,0) -> 0 | F7: =C7-E7*32 -> 8 | G7: =D7-E7*32 -> 5 | H7: RO | I7: =CONCATENATE(INDIRECT("template!I7")) -> Flush cache 0: Not Flush cache 1: Flush cache | J7: 0
A8: reserved | B8: 20 | C8: =D8+B8-1 -> 28 | D8: =INDIRECT(ADDRESS(ROW()-1,COLUMN()-1))+1 -> 9 | E8: =ROUNDDOWN(C8/32,0) -> 0 | F8: =C8-E8*32 -> 28 | G8: =D8-E8*32 -> 9 | H8: RO | I8: =CONCATENATE(INDIRECT("template!I8")) -> reserved | J8: 0
A9: Reserved | B9: 3 | C9: =D9+B9-1 -> 31 | D9: =INDIRECT(ADDRESS(ROW()-1,COLUMN()-1))+1 -> 29 | E9: =ROUNDDOWN(C9/32,0) -> 0 | F9: =C9-E9*32 -> 31 | G9: =D9-E9*32 -> 29 | H9: RO | I9: =CONCATENATE(INDIRECT("template!I9")) | J9: 0
A10: cmd_type | B10: 4 | C10: =D10+B10-1 -> 35 | D10: =INDIRECT(ADDRESS(ROW()-1,COLUMN()-1))+1 -> 32 | E10: =ROUNDDOWN(C10/32,0) -> 1 | F10: =C10-E10*32 -> 3 | G10: =D10-E10*32 -> 0 | H10: RW | I10: =CONCATENATE(INDIRECT("template!I10")) | J10: ASITIS
A11: cmd_special_function | B11: 3 | C11: =D11+B11-1 -> 38 | D11: =INDIRECT(ADDRESS(ROW()-1,COLUMN()-1))+1 -> 36 | E11: =ROUNDDOWN(C11/32,0) -> 1 | F11: =C11-E11*32 -> 6 | G11: =D11-E11*32 -> 4 | H11: RW | I11: =CONCATENATE(INDIRECT("DMA_matrix!I11")) | J11: ASITIS
A12: fill_constant_en | B12: 1 | C12: =D12+B12-1 -> 39 | D12: =INDIRECT(ADDRESS(ROW()-1,COLUMN()-1))+1 -> 39 | E12: =ROUNDDOWN(C12/32,0) -> 1 | F12: =C12-E12*32 -> 7 | G12: =D12-E12*32 -> 7 | H12: RW | I12: =CONCATENATE(INDIRECT("DMA_matrix!I12")) | J12: no need to config
A13: src_data_format | B13: 3 | C13: =D13+B13-1 -> 42 | D13: =INDIRECT(ADDRESS(ROW()-1,COLUMN()-1))+1 -> 40 | E13: =ROUNDDOWN(C13/32,0) -> 1 | F13: =C13-E13*32 -> 10 | G13: =D13-E13*32 -> 8 | H13: RW | I13: =CONCATENATE(INDIRECT("template!I13")) -> reserved | J13: ASITIS
A14: reserved | B14: 21 | C14: =D14+B14-1 -> 63 | D14: =INDIRECT(ADDRESS(ROW()-1,COLUMN()-1))+1 -> 43 | E14: =ROUNDDOWN(C14/32,0) -> 1 | F14: =C14-E14*32 -> 31 | G14: =D14-E14*32 -> 11 | H14: RO | I14: =CONCATENATE(INDIRECT("template!I14")) -> 0x0:GDMA_tensor 0x1:GDMA_matrix 0x2:GDMA_masked_select 0x3:GDMA_general 0x5:GDMA_nonzero 0x6:GDMA_sys 0x7:GDMA_gather 0x8:GDMA_scatter 0x9:GDMA_reverse 0xc:GDMA_lossy_compress 0xd:GDMA_lossy_decompress | J14: 0
A15: cmd_id_dep | B15: 24 | C15: =D15+B15-1 -> 87 | D15: =INDIRECT(ADDRESS(ROW()-1,COLUMN()-1))+1 -> 64 | E15: =ROUNDDOWN(C15/32,0) -> 2 | F15: =C15-E15*32 -> 23 | G15: =D15-E15*32 -> 0 | H15: RW | I15: =CONCATENATE(INDIRECT("template!I15")) -> this field is connected with cmd_type. when cmd_type == DMA_tensor 000: No special function 001: Enable transposition write (For Neuron transposition case, the dest_N= src_C, dest_C=src_N) 011: broadcast：only support C size<=64 and lmem mask invalid others: reserved | J15: ASITIS
A16: reserved | B16: 8 | C16: =D16+B16-1 -> 95 | D16: =INDIRECT(ADDRESS(ROW()-1,COLUMN()-1))+1 -> 88 | E16: =ROUNDDOWN(C16/32,0) -> 2 | F16: =C16-E16*32 -> 31 | G16: =D16-E16*32 -> 24 | H16: RO | I16: =CONCATENATE(INDIRECT("template!I16")) -> 0: no fill constant 1: fill constant enable | J16: ASITIS
A17: src_hstride/dst_hstride | B17: 32 | C17: =D17+B17-1 -> 127 | D17: =INDIRECT(ADDRESS(ROW()-1,COLUMN()-1))+1 -> 96 | E17: =ROUNDDOWN(C17/32,0) -> 3 | F17: =C17-E17*32 -> 31 | G17: =D17-E17*32 -> 0 | H17: RW | I17: if dst is lmem, this field is src hstride;if src is lmem,this field is dst hstride | J17: ASITIS
A18: dst_nstride/src_nstride | B18: 32 | C18: =D18+B18-1 -> 159 | D18: =INDIRECT(ADDRESS(ROW()-1,COLUMN()-1))+1 -> 128 | E18: =ROUNDDOWN(C18/32,0) -> 4 | F18: =C18-E18*32 -> 31 | G18: =D18-E18*32 -> 0 | H18: RW | I18: if dst is lmem, ths field is dst nstride; if src is lmem,this field is src nstride | J18: ASITIS
A19: dst_cstride/src_cstride | B19: 32 | C19: =D19+B19-1 -> 191 | D19: =INDIRECT(ADDRESS(ROW()-1,COLUMN()-1))+1 -> 160 | E19: =ROUNDDOWN(C19/32,0) -> 5 | F19: =C19-E19*32 -> 31 | G19: =D19-E19*32 -> 0 | H19: RW | I19: if dst is lmem, ths field is dst cstride; if src is lmem,this field is src cstride | J19: ASITIS
A20: src_hsize/dst_hsize | B20: 16 | C20: =D20+B20-1 -> 207 | D20: =INDIRECT(ADDRESS(ROW()-1,COLUMN()-1))+1 -> 192 | E20: =ROUNDDOWN(C20/32,0) -> 6 | F20: =C20-E20*32 -> 15 | G20: =D20-E20*32 -> 0 | H20: RW | I20: if dst is lmem, ths field is src hsize; if src is lmem,this field is dst hsize | J20: ASITIS
A21: src_wsize/dst_wsize | B21: 16 | C21: =D21+B21-1 -> 223 | D21: =INDIRECT(ADDRESS(ROW()-1,COLUMN()-1))+1 -> 208 | E21: =ROUNDDOWN(C21/32,0) -> 6 | F21: =C21-E21*32 -> 31 | G21: =D21-E21*32 -> 16 | H21: RW | I21: if dst is lmem, ths field is src wsize; if src is lmem,this field is dst wsize | J21: ASITIS
A22: dst_nsize/src_nsize | B22: 16 | C22: =D22+B22-1 -> 239 | D22: =INDIRECT(ADDRESS(ROW()-1,COLUMN()-1))+1 -> 224 | E22: =ROUNDDOWN(C22/32,0) -> 7 | F22: =C22-E22*32 -> 15 | G22: =D22-E22*32 -> 0 | H22: RW | I22: if dst is lmem, ths field is dst nsize; if src is lmem,this field is src nsize | J22: ASITIS
A23: dst_csize/src_csize | B23: 16 | C23: =D23+B23-1 -> 255 | D23: =INDIRECT(ADDRESS(ROW()-1,COLUMN()-1))+1 -> 240 | E23: =ROUNDDOWN(C23/32,0) -> 7 | F23: =C23-E23*32 -> 31 | G23: =D23-E23*32 -> 16 | H23: RW | I23: if dst is lmem, ths field is dst csize; if src is lmem,this field is src csize | J23: ASITIS
A24: dst_wsize/src_wsize | B24: 16 | C24: =D24+B24-1 -> 271 | D24: =INDIRECT(ADDRESS(ROW()-1,COLUMN()-1))+1 -> 256 | E24: =ROUNDDOWN(C24/32,0) -> 8 | F24: =C24-E24*32 -> 15 | G24: =D24-E24*32 -> 0 | H24: RW | I24: if dst is lmem, ths field is dst wsize; if src is lmem,this field is src wsize | J24: ASITIS
A25: reserved | B25: 16 | C25: =D25+B25-1 -> 287 | D25: =INDIRECT(ADDRESS(ROW()-1,COLUMN()-1))+1 -> 272 | E25: =ROUNDDOWN(C25/32,0) -> 8 | F25: =C25-E25*32 -> 31 | G25: =D25-E25*32 -> 16 | H25: RO | I25: reserved | J25: 0
A26: src_start_addr_l32 | B26: 32 | C26: =D26+B26-1 -> 319 | D26: =INDIRECT(ADDRESS(ROW()-1,COLUMN()-1))+1 -> 288 | E26: =ROUNDDOWN(C26/32,0) -> 9 | F26: =C26-E26*32 -> 31 | G26: =D26-E26*32 -> 0 | H26: RW | I26: =INDIRECT("template!I34") -> Source blob C | J26: ASITIS
A27: src_start_addr_h8 | B27: 8 | C27: =D27+B27-1 -> 327 | D27: =INDIRECT(ADDRESS(ROW()-1,COLUMN()-1))+1 -> 320 | E27: =ROUNDDOWN(C27/32,0) -> 10 | F27: =C27-E27*32 -> 7 | G27: =D27-E27*32 -> 0 | H27: RW | I27: =INDIRECT("template!I35") -> Source blob H | J27: ASITIS
A28: reserved | B28: 24 | C28: =D28+B28-1 -> 351 | D28: =INDIRECT(ADDRESS(ROW()-1,COLUMN()-1))+1 -> 328 | E28: =ROUNDDOWN(C28/32,0) -> 10 | F28: =C28-E28*32 -> 31 | G28: =D28-E28*32 -> 8 | H28: RO | I28: =INDIRECT("template!I36") -> Source blob W | J28: 0
A29: dst_start_addr_l32 | B29: 32 | C29: =D29+B29-1 -> 383 | D29: =INDIRECT(ADDRESS(ROW()-1,COLUMN()-1))+1 -> 352 | E29: =ROUNDDOWN(C29/32,0) -> 11 | F29: =C29-E29*32 -> 31 | G29: =D29-E29*32 -> 0 | H29: RW | I29: =INDIRECT("template!I37") -> Destination Blob Number | J29: ASITIS
A30: dst_start_addr_h8 | B30: 8 | C30: =D30+B30-1 -> 391 | D30: =INDIRECT(ADDRESS(ROW()-1,COLUMN()-1))+1 -> 384 | E30: =ROUNDDOWN(C30/32,0) -> 12 | F30: =C30-E30*32 -> 7 | G30: =D30-E30*32 -> 0 | H30: RW | I30: =INDIRECT("template!I38") -> Destination blob C | J30: ASITIS
A31: reserved | B31: 24 | C31: =D31+B31-1 -> 415 | D31: =INDIRECT(ADDRESS(ROW()-1,COLUMN()-1))+1 -> 392 | E31: =ROUNDDOWN(C31/32,0) -> 12 | F31: =C31-E31*32 -> 31 | G31: =D31-E31*32 -> 8 | H31: RO | I31: =INDIRECT("template!I39") -> Destination blob H | J31: 0
A32: reserved | B32: 32 | C32: =D32+B32-1 -> 447 | D32: =INDIRECT(ADDRESS(ROW()-1,COLUMN()-1))+1 -> 416 | E32: =ROUNDDOWN(C32/32,0) -> 13 | F32: =C32-E32*32 -> 31 | G32: =D32-E32*32 -> 0 | H32: RO | I32: reserved | J32: 0
A33: localmem_mask_l32 | B33: 32 | C33: =D33+B33-1 -> 479 | D33: =INDIRECT(ADDRESS(ROW()-1,COLUMN()-1))+1 -> 448 | E33: =ROUNDDOWN(C33/32,0) -> 14 | F33: =C33-E33*32 -> 31 | G33: =D33-E33*32 -> 0 | H33: RW | I33: =INDIRECT("template!I42") -> bit[7:0]=source blob start address[39:32] bit[12:8]=0: real address = start address[39:0] + csr_region[0]<<8 bit[12:8]=1: real address = start address[39:0] + csr_region[1]<<8 bit[12:8]=2: real address = start address[39:0] + csr_region[2]<<8 bit[12:8]=3: real address = start address[39:0] + csr_region[3]<<8 bit[12:8]=4: real address = start address[39:0] + csr_region[4]<<8 bit[12:8]=5: real address = start address[39:0] + csr_region[5]<<8 bit[12:8]=6: real address = start address[39:0] + csr_region[6]<<8 bit[12:8]=7: real address = start address[39:0] + csr_region[7]<<8 bit[12:8]=8: real address = start address[39:0] + csr_region[8]<<8 bit[12:8]=9: real address = start address[39:0] + csr_region[9]<<8 bit[12:8]=10: real address = start address[39:0] + csr_region[10]<<8 bit[12:8]=11: real address = start address[39:0] + csr_region[11]<<8 bit[12:8]=12: real address = start address[39:0] + csr_region[12]<<8 bit[12:8]=13: real address = start address[39:0] + csr_region[13]<<8 bit[12:8]=14: real address = start address[39:0] + csr_region[14]<<8 bit[12:8]=15: real address = start address[39:0] + csr_region[15]<<8 bit[12:8]=16: real address = start address[39:0] + csr_region[16]<<8 bit[12:8]=17: real address = start address[39:0] + csr_region[17]<<8 bit[12:8]=18: real address = start address[39:0] + csr_region[18]<<8 bit[12:8]=19: real address = start address[39:0] + csr_region[19]<<8 bit[12:8]=20: real address = start address[39:0] + csr_region[20]<<8 bit[12:8]=21: real address = start address[39:0] + csr_region[21]<<8 bit[12:8]=22: real address = start address[39:0] + csr_region[22]<<8 bit[12:8]=23: real address = start address[39:0] + csr_region[23]<<8 bit[12:8]=24: real address = start address[39:0] + csr_region[24]<<8 bit[12:8]=25: real address = start address[39:0] + csr_region[25]<<8 bit[12:8]=26: real address = start address[39:0] + csr_region[26]<<8 bit[12:8]=27: real address = start address[39:0] + csr_region[27]<<8 bit[12:8]=28: real address = start address[39:0] + csr_region[28]<<8 bit[12:8]=29: real address = start address[39:0] + csr_region[29]<<8 bit[12:8]=30: real address = start address[39:0] + csr_region[30]<<8 bit[12:8]=31: real address = start address[39:0] real address[39:32] == 'h69 & bit[12:8]==31 means src is tiu, otherwise, src is from DTN | J33: ASITIS
A34: localmem_mask_h32 | B34: 32 | C34: =D34+B34-1 -> 511 | D34: =INDIRECT(ADDRESS(ROW()-1,COLUMN()-1))+1 -> 480 | E34: =ROUNDDOWN(C34/32,0) -> 15 | F34: =C34-E34*32 -> 31 | G34: =D34-E34*32 -> 0 | H34: RW | I34: =INDIRECT("template!I43") -> reserved | J34: ASITIS
A35: RW: Read and writeable register
A36: RO: Read only register
A37: RTC: Read to clear register
A38: WTC: Write to clear register
