Workbook

Sheet Rev
B2: Rev | C2: Date | D2: Update description
B3: 0.1 | C3: 2025/2/8 | D3: 2260E init version, 修订 更新SYS指令中msg_id/dst_id/src_id为8/2/8bit; 删除cfg_plane_good配置
B4: 0.2 | C4: 2025/2/18 | D4: 删除长指令，LIN、VC des_cmd_short修正为384bit,cfg拆解128bit
B5: 0.3 | C5: 2025/2/19 | D5: 修复cfg_des_addr为33bit，删除对cfg_des_addr_end的支持 通过当前代码版本对齐配置信息，增加cfg_fbt_roi_pord_dis
B6: 0.4 | C6: 2025/2/21 | D6: 删除cfg_srd_id寄存器
B7: 0.5 | C7: 2025/2/26 | D7: 增加遗漏的cfg1高位32bit的cfgr_curr_cmdid配置信号
B8: 0.6 | C8: 2025/2/28 | D8: SYS指令中des_imm与rtl功能对齐-msg id取值方式继承2260
B9: 0.7 | C9: 2025/3/5 | D9: 更新Base Address
B10: 0.8 | C10: 2025/3/6 | D10: 与代码对齐0x100配置寄存器
B11: 0.9 | C11: 2025/4/21 | D11: 与tensor_extension_instruction_code_v2.0.14对齐
B12: 1 | C12: 2025/5/21 | D12: 与tensor_extension_instruction_code_v2.0.16对齐

Sheet Control register base=0x100
A1: Project Name | B1: 2260E
A2: Sub system | B2: tpu
A3: Module Name | B3: dpc_des_reg
A4: Address Width
A5: Main Clock | B5: clk
A6: Second Clock | B6: NA
A7: Main Reset | B7: rst_n
A8: Second Reset | B8: NA
A9: File Version | B9: V 0.2
A10: Creation Date | B10: 2/8/2025
A11: Base Address | B11: 800_0100
A12: //
A13: // Begin
A14: Reg High Address | B14: Reg Low Address | C14: Register Name | E14: Field | F14: Short Description | G14: Register Description | H14: Bits | I14: MSB | J14: LSB | K14: RW | L14: Init | M14: Field Description | N14: Mask | O14: check value | P14: shadow | Q14: shadow ctrl | R14: shadow read | S14: cross clock | T14: cross rst | U14: group | V14: Visibility | X14: Bits | Y14: MSB | Z14: LSB
A15: h04 | B15: h00 | C15: cfg0 | D15: cfg0_L | E15: cfg_en | H15: 1 | I15: =J15+H15-1 -> 0 | J15: 0 | K15: RW | L15: =H15&"'h0" -> 1'h0 | M15: TPU使能 | X15: 1 | Y15: =Z15+X15-1 -> 0 | Z15: 0 | AA15: cfg_reg
E16: cfg_intr_stat | H16: 1 | I16: =J16+H16-1 -> 1 | J16: =I15+1 -> 1 | K16: W1C | L16: =H16&"'h0" -> 1'h0 | M16: R/W1C TIU interrupt Status | X16: 1 | Y16: =Z16+X16-1 -> 1 | Z16: =Y15+1 -> 1
E17: cfgr_curr_cmdid | H17: 24 | I17: =J17+H17-1 -> 25 | J17: =I16+1 -> 2 | K17: RO | L17: =H17&"'h0" -> 24'h0 | M17: 上一个执行完的command id，32bit在cfg1可读 | X17: 24 | Y17: =Z17+X17-1 -> 25 | Z17: =Y16+1 -> 2
E18: cfg_instr_barrier | H18: 1 | I18: =J18+H18-1 -> 26 | J18: =I17+1 -> 26 | K18: RW | L18: =H18&"'h1" -> 1'h1 | M18: 指令barrier | X18: 1 | Y18: =Z18+X18-1 -> 26 | Z18: =Y17+1 -> 26
E19: cfg_data_barrier | H19: 1 | I19: =J19+H19-1 -> 27 | J19: =I18+1 -> 27 | K19: RW | L19: =H19&"'h1" -> 1'h1 | M19: 数据barrier | X19: 1 | Y19: =Z19+X19-1 -> 27 | Z19: =Y18+1 -> 27
E20: cfg_fb_pins_en | H20: 1 | I20: =J20+H20-1 -> 28 | J20: =I19+1 -> 28 | K20: RW | L20: =H20&"'h0" -> 1'h0 | M20: pad insv read buffer | X20: 1 | Y20: =Z20+X20-1 -> 28 | Z20: =Y19+1 -> 28
E21: cfg_fb_pxl_en | H21: 1 | I21: =J21+H21-1 -> 29 | J21: =I20+1 -> 29 | K21: RW | L21: =H21&"'h0" -> 1'h0 | M21: pxl read buffer | X21: 1 | Y21: =Z21+X21-1 -> 29 | Z21: =Y20+1 -> 29
E22: cfg_intr_en | H22: 1 | I22: =J22+H22-1 -> 30 | J22: =I21+1 -> 30 | K22: RW | L22: =H22&"'h1" -> 1'h1 | M22: TIU interrupt global enable | X22: 1 | Y22: =Z22+X22-1 -> 30 | Z22: =Y21+1 -> 30
E23: cfg_cmdbuf_intr_en | H23: 1 | I23: =J23+H23-1 -> 31 | J23: =I22+1 -> 31 | K23: RW | L23: =H23&"'h0" -> 1'h0 | M23: des buf interrupt enable | X23: 1 | Y23: =Z23+X23-1 -> 31 | Z23: =Y22+1 -> 31
E24: cfg_cmdbuf_avail | H24: 9 | I24: =J24+H24-1 -> 40 | J24: =I23+1 -> 32 | K24: RO | L24: =H24&"'h80" -> 9'h80 | M24: des buf剩余空间，cfg_cmdbuf_avail*128Byte, 最多128*128Byte | X24: 9 | Y24: =Z24+X24-1 -> 40 | Z24: =Y23+1 -> 32
E25: cfg_cmdbuf_avail | H25: 3 | I25: =J25+H25-1 -> 43 | J25: =I24+1 -> 41 | K25: RO | L25: =H25&"'h0" -> 3'h0 | M25: tie0 | X25: 3 | Y25: =Z25+X25-1 -> 43 | Z25: =Y24+1 -> 41
E26: cfg_cmdbuf_intr_biten | H26: 4 | I26: =J26+H26-1 -> 47 | J26: =I25+1 -> 44 | K26: RW | L26: =H26&"'h0" -> 4'h0 | M26: 使能cmdbuf中断 | X26: 4 | Y26: =Z26+X26-1 -> 47 | Z26: =Y25+1 -> 44
E27: cfg_cmdbuf_intr_stat | H27: 4 | I27: =J27+H27-1 -> 51 | J27: =I26+1 -> 48 | K27: RO | L27: =H27&"'h0" -> 4'h0 | M27: cmdbuf中断情况 | X27: 4 | Y27: =Z27+X27-1 -> 51 | Z27: =Y26+1 -> 48
E28: cfg_dma_ban_overlap | H28: 1 | I28: =J28+H28-1 -> 52 | J28: =I27+1 -> 52 | K28: RW | L28: =H28&"'h0" -> 1'h0 | M28: dma | X28: 1 | Y28: =Z28+X28-1 -> 52 | Z28: =Y27+1 -> 52
E29: cfg_dma_space_margin | H29: 1 | I29: =J29+H29-1 -> 53 | J29: =I28+1 -> 53 | K29: RW | L29: =H29&"'h0" -> 1'h0 | M29: dma总线，读出fifo空间控制 降低outstanding数量 | X29: 1 | Y29: =Z29+X29-1 -> 53 | Z29: =Y28+1 -> 53
E30: cfg_des_mode | H30: 1 | I30: =J30+H30-1 -> 54 | J30: =I29+1 -> 54 | K30: RO | L30: =H30&"'h0" -> 1'h0 | M30: des mode | X30: 1 | Y30: =Z30+X30-1 -> 54 | Z30: =Y29+1 -> 54
E31: cfg_des_clr_busy | H31: 1 | I31: =J31+H31-1 -> 55 | J31: =I30+1 -> 55 | K31: RO | L31: =H31&"'h0" -> 1'h0 | M31: 清除des buf里的指令 | X31: 1 | Y31: =Z31+X31-1 -> 55 | Z31: =Y30+1 -> 55
E32: cfg_fb_only_cmm2 | H32: 1 | I32: =J32+H32-1 -> 56 | J32: =I31+1 -> 56 | K32: RW | L32: =H32&"'h0" -> 1'h0 | M32: 只在conv mm2 pord的时候开启pxl/pins buffer | X32: 1 | Y32: =Z32+X32-1 -> 56 | Z32: =Y31+1 -> 56
E33: cfg_fb_conv_dis | H33: 1 | I33: =J33+H33-1 -> 57 | J33: =I32+1 -> 57 | K33: RW | L33: =H33&"'h0" -> 1'h0 | M33: conv指令下关闭pxl/pins buffer | X33: 1 | Y33: =Z33+X33-1 -> 57 | Z33: =Y32+1 -> 57
E34: cfg_fb_mm2_dis | H34: 1 | I34: =J34+H34-1 -> 58 | J34: =I33+1 -> 58 | K34: RW | L34: =H34&"'h0" -> 1'h0 | M34: mm2指令下关闭pxl/pins buffer | X34: 1 | Y34: =Z34+X34-1 -> 58 | Z34: =Y33+1 -> 58
E35: cfg_fb_mm2_nt_dis | H35: 1 | I35: =J35+H35-1 -> 59 | J35: =I34+1 -> 59 | K35: RW | L35: =H35&"'h0" -> 1'h0 | M35: mm2_nt指令下不打开pxl/pins buffer | X35: 1 | Y35: =Z35+X35-1 -> 59 | Z35: =Y34+1 -> 59
E36: cfg_fb_pord_dis | H36: 1 | I36: =J36+H36-1 -> 60 | J36: =I35+1 -> 60 | K36: RW | L36: =H36&"'h0" -> 1'h0 | M36: pord指令下不打开pxl/pins buffer | X36: 1 | Y36: =Z36+X36-1 -> 60 | Z36: =Y35+1 -> 60
... E39: cfg_rst_cmdid | H39: 1 | I39: =J39+H39-1 -> 63 | J39: =I38+1 -> 63 | K39: RW | L39: =H39&"'h0" -> 1'h0 | M39: 自动清0 | X39: 1 | Y39: =Z39+X39-1 -> 63 | Z39: =Y38+1 -> 63
A40: h0c | B40: h08 | D40: cfg0_H | E40: cfg_des_addr_vld | H40: 1 | I40: =J40+H40-1 -> 64 | J40: =I39+1 -> 64 | K40: RW | L40: =H40&"'h0" -> 1'h0 | M40: 使能descriptor模式 写1‘b1 使能 自动清0 | X40: 1 | Y40: =Z40+X40-1 -> 64 | Z40: =Y39+1 -> 64
E41: cfg_des_clr | H41: 1 | I41: =J41+H41-1 -> 65 | J41: =I40+1 -> 65 | K41: W1C | L41: =H41&"'h0" -> 1'h0 | M41: 写1清空des buf | X41: 1 | Y41: =Z41+X41-1 -> 65 | Z41: =Y40+1 -> 65
E42: cfg_des_addr | H42: 33 | I42: =J42+H42-1 -> 98 | J42: =I41+1 -> 66 | K42: RW | L42: =H42&"'h0" -> 33'h0 | M42: descriptor地址{cfg_des_addr, 7'b0} Descriptor结束通过sys end指令设置中断置位。 | X42: 33 | Y42: =Z42+X42-1 -> 98 | Z42: =Y41+1 -> 66
...

Sheet TGCR
A1: arch name | B1: Addr | C1: IDX | D1: Width(bit) | E1: Description | F1: A2 support | G1: Conv | H1: MM2 | I1: PorD | J1: MM
A2: T0 | B2: 0 | C2: 0 | D2: 32 | E2: opd0 addr | F2: N
A3: T1 | B3: 4 | C3: 1 | D3: 32 | E3: opd1 addr | F3: N
A4: T2 | B4: 8 | C4: 2 | D4: 32 | E4: opd2 addr | F4: N
A5: T3 | B5: 12 | C5: 3 | D5: 32 | E5: res0 addr | F5: N
A6: T4 | B6: 16 | C6: 4 | D6: 32 | E6: opd3 addr | F6: N
A7: T5 | B7: 20 | C7: 5 | D7: 32 | E7: opd4_addr | F7: Y | G7: 当kzp为常量时，kzp value；当kzp为变量时，kzp地址 | H7: Not used | I7: Not used | J7: Not used
A8: T6 | B8: 24 | C8: 6 | D8: 32 | E8: opd5_addr | F8: Y | G8: 量化参数地址；如果量化参数为常量，则当量化参数为常数时，multiplior | H8: 量化参数地址；如果量化参数为常量，则当量化参数为常数时，multiplior | I8: 量化参数地址；如果量化参数为常量，则当量化参数为常数时，multiplior | J8: Not used
A9: T7 | B9: 28 | C9: 7 | D9: 32 | E9: res1_addr | F9: N
A10: T8 | B10: 32 | C10: 8 | D10: 32 | E10: opd0 w | F10: N
A11: T9 | B11: 36 | C11: 9 | D11: 32 | E11: opd0 h | F11: N
A12: T10 | B12: 40 | C12: 10 | D12: 32 | E12: opd0 c | F12: N
A13: T11 | B13: 44 | C13: 11 | D13: 32 | E13: opd0 n | F13: N
A14: T12 | B14: 48 | C14: 12 | D14: 32 | E14: opd0 w stride | F14: N
A15: T13 | B15: 52 | C15: 13 | D15: 32 | E15: opd0 h stride | F15: N
A16: T14 | B16: 56 | C16: 14 | D16: 32 | E16: opd0 c stride | F16: N
A17: T15 | B17: 60 | C17: 15 | D17: 32 | E17: opd0 n stride | F17: N
A18: T16 | B18: 64 | C18: 16 | D18: 32 | E18: opd1 w | F18: N
A19: T17 | B19: 68 | C19: 17 | D19: 32 | E19: opd1 h | F19: N
A20: T18 | B20: 72 | C20: 18 | D20: 32 | E20: opd1 c | F20: N
... A33: T31 | B33: 124 | C33: 31 | D33: 32 | E33: res0 n stride | F33: N
A34: T32 | B34: 128 | C34: 32 | D34: 32 | E34: TGCR32 | F34: Y | G34: 当量化参数为常数时，移位参数 | H34: 当量化参数为常数时，移位参数 | I34: 当量化参数为常数时，移位参数 | J34: 当量化参数为常数时，移位参数
A35: T33 | B35: 132 | C35: 33 | D35: 32 | E35: TGCR33 | F35: Y | G35: 当量化参数为常数时，rzp | H35: 当量化参数为常数时，yzp | I35: 当量化参数为常数时，yzp | J35: 当量化参数为常数时，yzp
A36: T34 | B36: 136 | C36: 34 | D36: 32 | E36: TGCR34 | F36: N
A40: T127 | B40: 508 | C40: 127 | D40: 32 | E40: 0寄存器，写入无效，可以reg_idx为0xFF，表示一笔无效写入 | F40: Y
A41: T128 | B41: 512 | C41: 128 | D41: 1 | E41: 0：独立模式；1： 组合模式, reset0 | F41: Y
A42: T129 | B42: 516 | C42: 129 | D42: 24 | E42: 指令ID，每执行一条指令+1，可以通过指令sys_tr_wr写入指定值(这种情况下sys_tr_wr指令的cmd id是该指令写入的值) | F42: Y

Sheet Lmem bank constrain
A1: conv1 opd0=image opd1=kernel opd1=bias | B1: winograd opd0=image opd1=kernel opd1=bias | C1: conv2 opd0=image opd1=kernel | D1: depthwise opd0=image opd1=kernel opd2=bias | E1: pooling opd0=image opd1=kernel | F1: matrix1 opd0=left opd1=right opd2=bias | G1: matrix2 opd0=left opd1=right opd2=bias | H1: tensor | I1: table lookup opd0=index opd1=table | J1: lmem | K1: md_sum opd0 = A | L1: mdsfu opd0 = A | M1: mdscalar opd0 = A opd1 = B | N1: md_linear opd0 =A opd1 =B opd2 =Ｓ | O1: decomp opd0=index(tensor_i) opd1=data(tensor_c)
A2: can add result but ic*kh*kw must be larger than 31 | B2: no add result | C2: no add result | D2: no add result | E2: no add result | F2: can add result but left column must be larger than 32 | G2: no add result | H2: no add result | I2: no add result
A3: image != kernel | B3: image != kernel | C3: image != kernel | D3: image != kernel | E3: image != result | F3: left != right | G3: left != right | H3: result != opd0 | I3: result != opd0 | J3: result != opd0 | K3: result != opd0 | L3: result != opd0 | M3: result != opd0 | N3: result != opd0 | O3: result != opd0
A4: image != bias | B4: image != bias | C4: image != bias | D4: image != bias | F4: left != bias | G4: left != result | H4: result != opd1 | M4: result != opd1 | N4: result != opd1 | O4: result != opd1
A5: image != result | B5: image != result | C5: image != result | D5: image != result | F5: left != result | G5: right != result | H5: result != opd2 | M5: opd0 != opd1 | N5: result != opd2 | O5: opd0 != opd1
A6: kernel != result | B6: kernel != result | C6: kernel != result | D6: kernel != result | F6: right != result | N6: opd0 != opd1
A7: bias != result | B7: bias != result | C7: bias != result | D7: bias != result | F7: bias != result
A10: 每个 lane中的local memory分为8个bank
A11: local memory共2个read port 2个write port，对应EU的2读1写，GDMA有独立的写端口，GDMA与EU复用2个读接口，当有至少一个read port空闲的时候，GDMA才进行读操作
A12: GDMA的读写之间可以bank冲突
A13: GDMA的读写和EU操作之间可以bank冲突,性能会有损失
A14: EU的读写之间，读读之间可以有Bank冲突,性能会有损失

Sheet Descriptor mode
A1: 指令读取 TPU有两种方式获取指令，两种模式支持所有指令宽度，支持不同宽度指令混编 PIO 外部向TPU配置指令 DES TPU从memory读取指令
A2: PIO模式，MCU向TPU顺序配置指令，每条指令内的section是以section0~N(N=1, 2, 3, 4, 5, 6, 7)的方式顺序发送。TPU执行指令的顺序与MCU发送顺序须完全一致。TPU根据指令类型和section0[0]获取指令长度，待一条指令完整后执行。 TPU默认PIO模式
A3: DES模式，TPU从外部存储读取指令。指令在memory中顺序排放，并128bit对齐。每条指令内的section以section0~N(N=1, 2, 3, 7)的方式摆放。指令的排放是紧凑的。TPU根据指令类型和section0[0]获取指令长度，待一条指令完整后执行。 MCU须配置TPU指令起始地址，结束地址，然后配置TPU进入DES模式。TPU指令起始地址，顺序从memory读取指令，当TPU执行到SYS(end)指令后，TPU不在读取指令，并将其后的指令fluash掉。TPU执行指令的顺序须与memory中指令排放顺序一致。

Sheet Command register base=0x0
A1: field | B1: Length（bit） | C1: High（bit） | D1: Low（bit） | E1: RW | F1: Default | G1: descriptions | H1: CONV opd0=image opd1=kernel opd2=bias opd3=shift res0=result | I1: PorD opd0=image opd1=kernel opd2=bias(for depth width) | J1: MM opd0=left opd1=right opd2=bias | K1: MM2 opd0=left opd1=right opd2=bias | L1: VC opd0=X opd1=Y | M1: AR & SEG | N1: SFU opd0 = A | O1: LIN opd0 =A opd1 =B opd2 =Ｓ | P1: CMP opd0 =A opd1 =B opd2 =C opd3 =D | Q1: TRANS & BC | R1: RQ & DQ | S1: SG | T1: SGL
A2: des_cmd_short | B2: 1 | C2: =D2+B2-1 -> 0 | D2: 0 | E2: RW | F2: 0x0 | G2: 0: Long Des 1: Short Des | H2: ASITIS | I2: ASITIS | J2: ASITIS | K2: ASITIS | L2: ASITIS | M2: ASITIS | N2: ASITIS | O2: ASITIS | P2: ASITIS | Q2: ASITIS | R2: ASITIS | S2: ASITIS | T2: ASITIS
A3: des_op_code | B3: 16 | C3: =D3+B3-1 -> 16 | D3: =C2+1 -> 1 | E3: RW | F3: 0x0 | G3: 操作码 | H3: 0 | I3: ASITIS | J3: 0 | K3: ASITIS | L3: ASITIS | M3: ASITIS | N3: ASITIS | O3: ASITIS | P3: ASITIS | Q3: ASITIS | R3: ASITIS | S3: ASITIS | T3: ASITIS
A4: des_cmd_id_dep | B4: 23 | C4: =D4+B4-1 -> 39 | D4: =C3+1 -> 17 | E4: RW | F4: 0x0 | G4: Dependency CMD ID 等待des_cmd_id_en指定外部eng ID完成后, 方可执行本descriptor | H4: ASITIS | I4: ASITIS | J4: ASITIS | K4: ASITIS | L4: ASITIS | M4: ASITIS | N4: ASITIS | O4: ASITIS | P4: ASITIS | Q4: ASITIS | R4: ASITIS | S4: ASITIS | T4: ASITIS
A5: des_dbg_mode | B5: 1 | C5: =D5+B5-1 -> 40 | D5: =C4+1 -> 40 | E5: RW | F5: 0x0 | G5: debug single_step des_mode | H5: ASITIS | I5: ASITIS | J5: ASITIS | K5: ASITIS | L5: ASITIS | M5: ASITIS | N5: ASITIS | O5: ASITIS | P5: ASITIS | Q5: ASITIS | R5: ASITIS | S5: ASITIS | T5: ASITIS
A6: des_tsk_typ | B6: 4 | C6: =D6+B6-1 -> 44 | D6: =C5+1 -> 41 | E6: RW | F6: 0x0 | G6: 指令任务类型 0: convolution 1: depthwise or pooling 2: matrix multiply && matrix multiply2 3: arithmetic && SEG 4: RQ && DQ 5: TRANS && BC 6: scatter_gather && scatter_gather_line 7: linear_arithmetic 8: rand_gen 9: special_function 10: fused_linear 11: not support 12: SYS_TR_WR 13: fused_cmpare 14: vector correlation 15: system | H6: ASITIS | I6: ASITIS | J6: ASITIS | K6: ASITIS | L6: ASITIS | M6: ASITIS | N6: ASITIS | O6: ASITIS | P6: ASITIS | Q6: ASITIS | R6: ASITIS | S6: 0 | T6: ASITIS
A7: des_tsk_eu_typ | B7: 5 | C7: =D7+B7-1 -> 49 | D7: =C6+1 -> 45 | E7: RW | F7: 0x0 | G7: 指令操作类型 根据指令类型指定 | H7: ASITIS | I7: ASITIS | J7: ASITIS | K7: ASITIS | L7: ASITIS | M7: ASITIS | N7: ASITIS | O7: ASITIS | P7: ASITIS | Q7: ASITIS | R7: ASITIS | S7: 0 | T7: ASITIS
A8: des_opt_rq | B8: 1 | C8: =D8+B8-1 -> 50 | D8: =C7+1 -> 50 | E8: RW | F8: 0x0 | G8: 是否对结果做量化 | H8: ASITIS | I8: ((des_tsk_eu_typ_reg == `DES_PORD_MAXP || des_tsk_eu_typ_reg == `DES_PORD_MINP || des_tsk_eu_typ_reg == `DES_PORD_RMAXP || des_tsk_eu_typ_reg == `DES_PORD_RMINP ) ? 1'd0 : des_opt_rq_reg) | J8: ((des_tsk_eu_typ_reg == `DES_MM_NORMAL) && (des_opt_opd0_prec_reg == `INT32 )) ? 1'b0 : des_opt_rq_reg | K8: ASITIS | L8: 0 | M8: 0 | N8: 0 | O8: 0 | P8: 0 | Q8: 0 | R8: 0 | S8: 0 | T8: 0
A9: des_tsk_opd_num | B9: 2 | C9: =D9+B9-1 -> 52 | D9: =C8+1 -> 51 | E9: RW | F9: 0x2 | G9: 输入操作数数目 0: 4个操作数 1: 1个操作数 2: 2个操作数_x000D_ 3: 3个操作数_x000D_ | H9: 0 | I9: ((des_tsk_eu_typ_reg == `DES_PORD_MAXP || des_tsk_eu_typ_reg == `DES_PORD_AVGP ) ? 2'd3 : 2'd0) | J9: (((des_tsk_eu_typ_reg == `DES_MM_NORMAL) && (des_opt_opd0_prec_reg == `INT8 || des_opt_opd0_prec_reg == `INT16)) ? 2'd2 : ((des_tsk_eu_typ_reg == `DES_MM_NORMAL) && (des_opt_opd0_prec_reg == `INT32 || des_opt_opd0_prec_reg == `FP32)) ? 2'd3: 2'd0) | K9: ((des_opt_opd0_prec_reg == `INT8) ? 2'd0 : 2'd3) | L9: ((des_tsk_eu_typ_reg == `DES_VC_SELG || des_tsk_eu_typ_reg == `DES_VC_SELL || des_tsk_eu_typ_reg == `DES_VC_SELE) ? 2'd3 : 2'd2) | M9: 1 | N9: ((des_tsk_eu_typ_reg == `DES_SFU_TAILOR) ? 2'd2 : 2'd1) | O9: ((des_tsk_eu_typ_reg == `DES_LIN_MAC) ? 2'd3 : 2'd2) | P9: 0 | Q9: 1 | R9: 2 | S9: ((des_tsk_eu_typ_reg == `DES_SGPE_S_NONZ || des_tsk_eu_typ_reg == `DES_SGPE_S_NONHZD) ? 2'd1 : 2'd2) | T9: 2
A10: des_pad_mode | B10: 2 | C10: =D10+B10-1 -> 54 | D10: =C9+1 -> 53 | E10: RW | F10: 0x0 | G10: 如果指令类型是CONV, 则 padding mode 其他, reserved0 | H10: ASITIS | I10: ASITIS | J10: 0 | K10: 0 | L10: 0 | M10: 0 | N10: 0 | O10: 0 | P10: 0 | Q10: 0 | R10: 0 | S10: 0 | T10: 0
A11: des_opt_res0_sign | B11: 1 | C11: =D11+B11-1 -> 55 | D11: =C10+1 -> 55 | E11: RW | F11: 0x0 | G11: 结果是INT型时，指明结果是有符号数还是无符号数 0: 无符号 1: 有符号 结果数据类型是FP8时，opd2为152格式或143格式 0：152格式 1：143格式 | H11: ASITIS | I11: ASITIS | J11: ASITIS | K11: ASITIS
A12: des_rsvd0 | B12: 3 | C12: =D12+B12-1 -> 58 | D12: =C11+1 -> 56 | E12: RW | F12: 0x0 | G12: reserved0 | H12: 0 | I12: 0 | J12: 0 | K12: 0 | L12: 0 | M12: 0 | N12: 0 | O12: 0 | P12: 0 | Q12: 0 | R12: 0 | S12: 0 | T12: 0
A13: des_pwr_step | B13: 4 | C13: =D13+B13-1 -> 62 | D13: =C12+1 -> 59 | E13: RW | F13: 0x0 | G13: power step | H13: ASITIS | I13: ASITIS | J13: ASITIS | K13: ASITIS | L13: ASITIS | M13: ASITIS | N13: ASITIS | O13: ASITIS | P13: ASITIS | Q13: ASITIS | R13: ASITIS | S13: ASITIS | T13: ASITIS
A14: des_intr_en | B14: 1 | C14: =D14+B14-1 -> 63 | D14: =C13+1 -> 63 | E14: RW | F14: 0x0 | G14: 0: 该指令执行结束不发出intr 1: 该指令执行结束发出intr | H14: ASITIS | I14: ASITIS | J14: ASITIS | K14: ASITIS | L14: ASITIS | M14: ASITIS | N14: ASITIS | O14: ASITIS | P14: ASITIS | Q14: ASITIS | R14: ASITIS | S14: ASITIS | T14: ASITIS
A15: des_opt_res_add | B15: 1 | C15: =D15+B15-1 -> 64 | D15: =C14+1 -> 64 | E15: RW | F15: 0x0 | G15: 结果是否和原res0_addr地址的内容累加 | H15: ASITIS | I15: 0 | J15: ASITIS | K15: ASITIS | L15: 0 | M15: ASITIS | N15: 0 | O15: 0 | P15: 0 | Q15: 0 | R15: 0 | S15: 0 | T15: 0
A16: des_opt_relu | B16: 1 | C16: =D16+B16-1 -> 65 | D16: =C15+1 -> 65 | E16: RW | F16: 0x1 | G16: reserved0 | H16: ASITIS | I16: ASITIS | J16: ASITIS | K16: ASITIS | L16: 1 | M16: 0 | N16: 0 | O16: 0 | P16: 0 | Q16: 0 | R16: 1 | S16: 0 | T16: 0
A17: des_opt_left_tran | B17: 1 | C17: =D17+B17-1 -> 66 | D17: =C16+1 -> 66 | E17: RW | F17: 0x0 | G17: 是否转置，只用在矩阵乘 | H17: 0 | I17: 0 | J17: ASITIS | K17: 0 | L17: 0 | M17: 0 | N17: 0 | O17: 0 | P17: 0 | Q17: 0 | R17: 0 | S17: 0 | T17: 0
A18: des_opt_opd4_const | B18: 1 | C18: =D18+B18-1 -> 67 | D18: =C17+1 -> 67 | E18: RW | F18: 0x0 | G18: opd4是否为常数 | H18: ASITIS | I18: 0 | J18: 0 | K18: ASITIS | L18: 0 | M18: 0 | N18: 0 | O18: 0 | P18: 0 | Q18: 0 | R18: 0 | S18: 0 | T18: 0
A19: des_opt_kernel_rotate | B19: 1 | C19: =D19+B19-1 -> 68 | D19: =C18+1 -> 68 | E19: RW | F19: 0x0 | G19: kernel是否转置 | H19: ASITIS | I19: ASITIS | J19: 0 | K19: 0 | L19: 0 | M19: 0 | N19: 0 | O19: 0 | P19: 0 | Q19: 0 | R19: 0 | S19: 0 | T19: 0
A20: des_opt_opd0_sign | B20: 1 | C20: =D20+B20-1 -> 69 | D20: =C19+1 -> 69 | E20: RW | F20: 0x0 | G20: opd0数据类型是INT8时，opd0是否为有符号数 0: 无符号数 1: 有符号数 opd0数据类型是FP8时，opd0为152格式或143格式 0：152格式 1：143格式 | H20: ASITIS | I20: ASITIS | J20: ASITIS | K20: ASITIS | L20: ASITIS | M20: 0 | N20: 0 | O20: ASITIS | P20: ASITIS | Q20: 0 | R20: ASITIS | S20: 0 | T20: 0
A21: des_opt_opd1_sign | B21: 1 | C21: =D21+B21-1 -> 70 | D21: =C20+1 -> 70 | E21: RW | F21: 0x1 | G21: opd1数据类型是INT8时，opd1是否为有符号数 0: 无符号数 1: 有符号数 opd1数据类型是FP8时，opd1为152格式或143格式 0：152格式 1：143格式 | H21: ASITIS | I21: ASITIS | J21: ASITIS | K21: ASITIS | L21: ASITIS | M21: 0 | N21: 0 | O21: ASITIS | P21: des_opt_opd0_sign_reg | Q21: 0 | R21: 1 | S21: 0 | T21: 0
A22: des_opt_opd2_sign | B22: 1 | C22: =D22+B22-1 -> 71 | D22: =C21+1 -> 71 | E22: RW | F22: 0x1 | G22: opd2数据类型是INT8时，opd2是否为有符号数 0: 无符号数 1: 有符号数 opd2数据类型是FP8时，opd2为152格式或143格式 0：152格式 1：143格式 | H22: ASITIS | I22: ASITIS | J22: ASITIS | K22: ASITIS | L22: 1 | M22: 0 | N22: 0 | O22: ASITIS | P22: ASITIS | Q22: 1 | R22: ASITIS | S22: 0 | T22: 0
A23: des_opt_res0_prec | B23: 3 | C23: =D23+B23-1 -> 74 | D23: =C22+1 -> 72 | E23: RW | F23: 0x2 | G23: res0数据类型 0: INT8 1: FP16 2: FP32 3: INT16 4: INT32 5: BFP16 6: INT4 7：FP8 | H23: ASITIS | I23: ASITIS | J23: ASITIS | K23: ASITIS | L23: ASITIS | M23: ASITIS | N23: ASITIS | O23: ASITIS | P23: ((des_tsk_eu_typ_reg == `DES_CMP_GSELG || des_tsk_eu_typ_reg == `DES_CMP_LSELL) ? des_opt_opd0_prec_reg : des_opt_opd2_prec_reg) | Q23: ASITIS | R23: ASITIS | S23: ASITIS | T23: ASITIS
A24: des_opt_opd0_prec | B24: 3 | C24: =D24+B24-1 -> 77 | D24: =C23+1 -> 75 | E24: RW | F24: 0x2 | G24: opd0数据类型 0: INT8 1: FP16 2: FP32 3: INT16 4: INT32 5: BFP16 6: INT4 7：FP8 | H24: ASITIS | I24: ASITIS | J24: ASITIS | K24: ASITIS | L24: ASITIS | M24: 4 | N24: ASITIS | O24: des_opt_res0_prec_reg | P24: ASITIS | Q24: des_opt_res0_prec_reg | R24: ASITIS | S24: ASITIS | T24: des_opt_res0_prec_reg
A25: des_opt_opd1_prec | B25: 3 | C25: =D25+B25-1 -> 80 | D25: =C24+1 -> 78 | E25: RW | F25: 0x2 | G25: opd1数据类型 0: INT8 1: FP16 2: FP32 3: INT16 4: INT32 5: BFP16 6: INT4 7：FP8 | H25: ASITIS | I25: des_opt_opd0_prec_reg | J25: des_opt_opd0_prec_reg | K25: ASITIS | L25: ASITIS | M25: 4 | N25: des_opt_opd0_prec_reg | O25: des_opt_res0_prec_reg | P25: des_opt_opd0_prec_reg | Q25: 2 | R25: 4 | S25: ASITIS | T25: ASITIS
A26: des_opt_opd2_prec | B26: 3 | C26: =D26+B26-1 -> 83 | D26: =C25+1 -> 81 | E26: RW | F26: 0x2 | G26: opd2数据类型 0: INT8 1: FP16 2: FP32 3: INT16 4: INT32 5: BFP16 6: INT4 7：FP8 | H26: ((des_opt_opd0_prec_reg == `INT8) ? `INT32 : des_opt_opd2_prec_reg) | I26: ((des_tsk_eu_typ_reg == `DES_PORD_DW) && (des_opt_opd0_prec_reg == `INT8) ? `INT32 : des_opt_opd0_prec_reg ) | J26: (((des_tsk_eu_typ_reg == `DES_MM_NORMAL) && (des_opt_opd0_prec_reg == `INT32)) ? `INT8 : ((des_tsk_eu_typ_reg == `DES_MM_NORMAL) && (des_opt_opd0_prec_reg == `FP32)) ? `FP32 : `INT32) | K26: ((des_opt_opd0_prec_reg == `INT8 || des_opt_opd0_prec_reg == `INT4) ? `INT32 : `FP32) | L26: des_opt_res0_prec_reg | M26: 4 | N26: 0 | O26: des_opt_res0_prec_reg | P26: ASITIS | Q26: 2 | R26: 0 | S26: 0 | T26: 0
A27: des_opt_opd0_const | B27: 1 | C27: =D27+B27-1 -> 84 | D27: =C26+1 -> 84 | E27: RW | F27: 0x0 | G27: opd0是否常数_x000D_, 如果是常数的话, 其值在des_opd0_addr中 0: 非常数 1: 常数 | H27: 0 | I27: 0 | J27: ASITIS | K27: ASITIS | L27: 0 | M27: 0 | N27: 0 | O27: 0 | P27: ASITIS | Q27: 0 | R27: 0 | S27: 0 | T27: 0
A28: des_opt_opd1_const | B28: 1 | C28: =D28+B28-1 -> 85 | D28: =C27+1 -> 85 | E28: RW | F28: 0x0 | G28: opd1是否常数, 如果是常数的话，其值在des_opd1_addr中 0: 非常数 1: 常数 | H28: ASITIS | I28: ASITIS | J28: 0 | K28: ASITIS | L28: 0 | M28: 0 | N28: 0 | O28: ASITIS | P28: ASITIS | Q28: 0 | R28: ASITIS | S28: 0 | T28: 0
A29: des_opt_opd2_const | B29: 1 | C29: =D29+B29-1 -> 86 | D29: =C28+1 -> 86 | E29: RW | F29: 0x0 | G29: opd2是否常数, 如果是常数的话，其值在des_opd1_addr中 0: 非常数 1: 常数 | H29: ASITIS | I29: ASITIS | J29: ASITIS | K29: ASITIS | L29: 0 | M29: 0 | N29: 0 | O29: ASITIS | P29: ASITIS | Q29: 0 | R29: 0 | S29: ASITIS | T29: ASITIS
A30: des_short_res0_str | B30: 3 | C30: =D30+B30-1 -> 89 | D30: =C29+1 -> 87 | E30: RW | F30: 0x0 | G30: res0数据存储格式 0: 对齐, 即 W_STRIDE=1 H_STRIDE=W C_STRIDE=EU_NUM*roundup(H*W/EU_NUM) N_STRIDE=C_STRIDE*roundup(C+C_START/LANE_NUM) 1: 紧密, 即 W_STRIDE=1 H_STRIDE=W C_STRIDE=W*H N_STRIDE=roundup(C+C_START/LANE_NUM)*C_STRIDE conv_neuron_/ winograd kernel的C对应OC，kernel的N对应IC 2: 偏置, 即 N_STRIDE=H_STRIDE=W_STRIDE=0 C_STRIDE=1 (depthwise中的kernel，以及md_sum的结果, conv/depthwise的bias使用该存储格式) 3: 张量，看具体配置 others: not support | H30: 0 | I30: 0 | J30: 0 | K30: 0 | L30: 0 | M30: ASITIS | N30: 0 | O30: 0 | P30: 0 | Q30: ((des_tsk_eu_typ_reg == `DES_TRANS_CWTRAN) ? 3'd3 : (des_tsk_eu_typ_reg == `DES_BC_SDIS) ? 3'd1 : 3'd0) | R30: 0 | S30: 0 | T30: 3
A31: des_short_opd0_str | B31: 3 | C31: =D31+B31-1 -> 92 | D31: =C30+1 -> 90 | E31: RW | F31: 0x0 | G31: opd0数据存储格式 0: 对齐, 即 W_STRIDE=1 H_STRIDE=W C_STRIDE=EU_NUM*roundup(H*W/EU_NUM) N_STRIDE=C_STRIDE*roundup(C+C_START/LANE_NUM) 1: 紧密, 即 W_STRIDE=1 H_STRIDE=W C_STRIDE=W*H N_STRIDE=roundup(C+C_START/LANE_NUM)*C_STRIDE 2: 偏置, 即 N_STRIDE=H_STRIDE=W_STRIDE=0 C_STRIDE=1 (depthwise中的kernel，以及md_sum的结果, conv/depthwise的bias使用该存储格式) 3: 张量，看具体配置 others: not support | H31: ASITIS | I31: 0 | J31: 0 | K31: 0 | L31: 0 | M31: ASITIS | N31: 0 | O31: 0 | P31: ASITIS | Q31: 0 | R31: 0 | S31: ASITIS | T31: ASITIS
... A89: des_opd3_addr | B89: 32 | C89: =D89+B89-1 -> 1023 | D89: =C88+1 -> 992 | E89: RW | F89: 0x0 | G89: 如果des_opt_opd3_const为0, opd3起始地址 如果des_opt_opd3_const为1, opd3常数 | H89: ASITIS | I89: ASITIS | J89: 0 | K89: 0 | L89: 0 | M89: 0 | N89: 0 | O89: 0 | P89: ASITIS | Q89: 0 | R89: 0 | S89: ASITIS | T89: 0
G92: 必须配
G93: 硬件可推导的指令filed，无需软件配置
G94: 无需软件配置，且不影响硬件行为的field
A96: macro_res0_000_c_str = (`EU_NUM*((des_res0_h_hw*des_res0_w_hw+`EU_NUM)/`EU_NUM));
A97: macro_res0_000_n_str = macro_res0_000_c_str*(des_res0_c_hw+(des_res0_addr_hw>>(`ADDR_BITS+`LANE_BITS))+`LANE_NUM)>>`LANE_NUM_LOG2;
A99: macro_res0_001_c_str = des_res0_h_hw*des_res0_w_hw;
A100: macro_res0_001_n_str = macro_res0_001_c_str*des_res0_c_hw;
A102: macro_res0_003_h_str = (`EU_NUM*((des_res0_w+`EU_NUM)/`EU_NUM));
...

Sheet sCONV
A1: field | B1: Length（bit） | C1: High（bit） | D1: Low（bit） | E1: RW | F1: Default | G1: descriptions | H1: conv_neuron opd0=image opd1=kernel opd2=bias/kzp res0=result | I1: Code
A2: ='Command register base=0x0'!A2 -> des_cmd_short | B2: ='Command register base=0x0'!B2 -> 1 | C2: =D2+B2-1 -> 0 | D2: 0 | E2: RW | F2: ='Command register base=0x0'!F2 -> 0x0 | G2: 1: 512bit | H2: ASITIS | I2: 0
A3: des_sym_range | B3: 1 | C3: =D3+B3-1 -> 1 | D3: =C2+1 -> 1 | E3: RW | F3: 0x0 | G3: conv/mm2结果量化，是否做对称饱和: 0: 不做对称饱和 1: 做对称饱和 | H3: ASITIS | I3: 0
A4: des_opt_opd4_const | B4: 1 | C4: =D4+B4-1 -> 2 | D4: =C3+1 -> 2 | E4: RW | F4: 0x0 | G4: 当opd0数据类型时INT8，INT4时，KZP是否为常数 0: 非常数 1: 常数 | H4: ASITIS | I4: 0
A5: des_opt_opd5_const | B5: 1 | C5: =D5+B5-1 -> 3 | D5: =C4+1 -> 3 | E5: RW | F5: 0x0 | G5: conv/mm2结果量化，量化参数是否常数 0: 非常数 1: 常数 | H5: ASITIS | I5: 0
A6: des_opt_relu | B6: 1 | C6: =D6+B6-1 -> 4 | D6: =C5+1 -> 4 | E6: RW | F6: 0x0 | G6: 对结果是否做relu 0: 不做relu操作 1: 做relu操作 | H6: ASITIS | I6: 0
A7: des_opt_rq | B7: 1 | C7: =D7+B7-1 -> 5 | D7: =C6+1 -> 5 | E7: RW | F7: 0x0 | G7: 结果是否做量化 0: 不做量化 1: 做量化 | H7: ASITIS | I7: 0
A8: des_opd2_n_str | B8: 3 | C8: =D8+B8-1 -> 8 | D8: =C7+1 -> 6 | E8: RW | F8: ='Command register base=0x0'!F13 -> 0x0 | G8: des_opd2_n_str[2:0]: 0: round_to_even 1: half round up 2: round to zero 3: floor 4: ceil | H8: ASITIS | I8: 0
A9: des_opt_opd1_prec | B9: 3 | C9: =D9+B9-1 -> 11 | D9: =C8+1 -> 9 | E9: RW | F9: ='Command register base=0x0'!F14 -> 0x0 | G9: opd1数据类型 0: INT8 1: FP16 2: FP32 3: INT16 4: INT32 5: BFP16 6: INT4 7：FP8 | H9: ASITIS | I9: 0
A10: ='Command register base=0x0'!A3 -> des_op_code | B10: 5 | C10: =D10+B10-1 -> 16 | D10: =C9+1 -> 12 | E10: RW | F10: ='Command register base=0x0'!F3 -> 0x0 | G10: reserved0 | H10: 0 | I10: 2
A11: ='Command register base=0x0'!A4 -> des_cmd_id_dep | B11: ='Command register base=0x0'!B4 -> 23 | C11: =D11+B11-1 -> 39 | D11: =C10+1 -> 17 | E11: RW | F11: ='Command register base=0x0'!F4 -> 0x0 | G11: Dependency CMD ID 等待des_cmd_id_en指定外部eng ID完成后, 方可执行本descriptor | H11: ASITIS | I11: 0
A12: ='Command register base=0x0'!A5 -> des_dbg_mode | B12: ='Command register base=0x0'!B5 -> 1 | C12: =D12+B12-1 -> 40 | D12: =C11+1 -> 40 | E12: RW | F12: ='Command register base=0x0'!F5 -> 0x0 | G12: debug single_step des_mode | H12: ASITIS
A13: ='Command register base=0x0'!A6 -> des_tsk_typ | B13: ='Command register base=0x0'!B6 -> 4 | C13: =D13+B13-1 -> 44 | D13: =C12+1 -> 41 | E13: RW | F13: ='Command register base=0x0'!F6 -> 0x0 | G13: 指令任务类型 0: conv | H13: ASITIS | I13: 0
A14: ='Command register base=0x0'!A7 -> des_tsk_eu_typ | B14: ='Command register base=0x0'!B7 -> 5 | C14: =D14+B14-1 -> 49 | D14: =C13+1 -> 45 | E14: RW | F14: ='Command register base=0x0'!F7 -> 0x0 | G14: des_tsk_eu_typ[4:0]指令操作类型， 0: CONV_NORMAL 2: CONV_TF32 | H14: ASITIS | I14: 0
A15: ='Command register base=0x0'!A20 -> des_opt_opd0_sign | B15: ='Command register base=0x0'!B20 -> 1 | C15: =D15+B15-1 -> 50 | D15: =C14+1 -> 50 | E15: RW | F15: ='Command register base=0x0'!F20 -> 0x0 | G15: opd0数据类型是INT8时, opd0是否为有符号数 0: 无符号数 1: 有符号数 | H15: ASITIS | I15: 0
A16: des_opt_opd1_sign | B16: ='Command register base=0x0'!B21 -> 1 | C16: =D16+B16-1 -> 51 | D16: =C15+1 -> 51 | E16: RW | F16: ='Command register base=0x0'!F21 -> 0x1 | G16: opd1数据类型是INT8时, opd1是否为有符号数 0: 无符号数 1: 有符号数 | H16: ASITIS | I16: 0
A17: des_opt_opd2_sign | B17: ='Command register base=0x0'!B22 -> 1 | C17: =D17+B17-1 -> 52 | D17: =C16+1 -> 52 | E17: RW | F17: ='Command register base=0x0'!F22 -> 0x1 | G17: opd2数据类型是INT8时, opd2是否为有符号数 0: 无符号数 1: 有符号数 | H17: ASITIS | I17: 0
A18: des_pad_mode | B18: 2 | C18: =D18+B18-1 -> 54 | D18: =C17+1 -> 53 | E18: RW | F18: 0x0 | G18: padding mode: 0: Constant 1: Reflection 2: Replication 3: Circular | H18: ASITIS | I18: 0
A19: des_opt_res0_sign | B19: 1 | C19: =D19+B19-1 -> 55 | D19: =C18+1 -> 55 | E19: RW | F19: 0x0 | G19: res0是INT型时，指明结果是有符号数还是无符号数 0: 无符号 1: 有符号 结果数据类型是FP8时，opd2为152格式或143格式 0：152格式 1：143格式 | H19: ASITIS | I19: 0
A20: des_opt_opd2_prec | B20: 3 | C20: =D20+B20-1 -> 58 | D20: =C19+1 -> 56 | E20: RW | F20: ='Command register base=0x0'!F12 -> 0x0 | G20: opd2数据类型 0: INT8 1: FP16 2: FP32 3: INT16 4: INT32 5: BFP16 6: INT4 7：FP8 | H20: ASITIS | I20: 0
A21: des_pwr_step | B21: 4 | C21: =D21+B21-1 -> 62 | D21: =C20+1 -> 59 | E21: RW | F21: 0x0 | G21: power step | H21: ASITIS | I21: 0
A22: des_opt_res_add | B22: 1 | C22: =D22+B22-1 -> 63 | D22: =C21+1 -> 63 | E22: RW | F22: 0x0 | G22: 如果指令操作类型是CONV_NORMAL, 0: 不做result add 1: 做result add 其他，reserved | H22: ASITIS | I22: 0
A23: ='Command register base=0x0'!A19 -> des_opt_kernel_rotate | B23: ='Command register base=0x0'!B19 -> 1 | C23: =D23+B23-1 -> 64 | D23: =C22+1 -> 64 | E23: RW | F23: ='Command register base=0x0'!F19 -> 0x0 | G23: kernel是否旋转 | H23: ASITIS | I23: 0
A24: ='Command register base=0x0'!A23 -> des_opt_res0_prec | B24: ='Command register base=0x0'!B23 -> 3 | C24: =D24+B24-1 -> 67 | D24: =C23+1 -> 65 | E24: RW | F24: ='Command register base=0x0'!F23 -> 0x2 | G24: res0数据类型 0: INT8 1: FP16 2: FP32 3: INT16 4: INT32 5: BFP16 6: INT4 7：FP8 | H24: ASITIS | I24: 0
A25: ='Command register base=0x0'!A24 -> des_opt_opd0_prec | B25: ='Command register base=0x0'!B24 -> 3 | C25: =D25+B25-1 -> 70 | D25: =C24+1 -> 68 | E25: RW | F25: ='Command register base=0x0'!F24 -> 0x2 | G25: opd0数据类型 0: INT8 1: FP16 2: FP32 3: INT16 4: INT32 5: BFP16 6: INT4 7：FP8 | H25: ASITIS | I25: 0
A26: ='Command register base=0x0'!A28 -> des_opt_opd1_const | B26: ='Command register base=0x0'!B28 -> 1 | C26: =D26+B26-1 -> 71 | D26: =C25+1 -> 71 | E26: RW | F26: ='Command register base=0x0'!F28 -> 0x0 | G26: 0: kernel非常数 1: kernel常数 | H26: ASITIS | I26: 0
A27: ='Command register base=0x0'!A29 -> des_opt_opd2_const | B27: ='Command register base=0x0'!B29 -> 1 | C27: =D27+B27-1 -> 72 | D27: =C26+1 -> 72 | E27: RW | F27: ='Command register base=0x0'!F29 -> 0x0 | G27: 0: bias非常数 1: bias常数 | H27: ASITIS | I27: 0
A28: ='Command register base=0x0'!A43 -> des_opd0_up_pad | B28: ='Command register base=0x0'!B43 -> 4 | C28: =D28+B28-1 -> 76 | D28: =C27+1 -> 73 | E28: RW | F28: ='Command register base=0x0'!F43 -> 0x0 | G28: opd0上方padding行数_x000D_, 0-15有效 | H28: ASITIS | I28: 0
A29: ='Command register base=0x0'!A44 -> des_opd0_dn_pad | B29: ='Command register base=0x0'!B44 -> 4 | C29: =D29+B29-1 -> 80 | D29: =C28+1 -> 77 | E29: RW | F29: ='Command register base=0x0'!F44 -> 0x0 | G29: opd0下方padding行数_x000D_, 0-15有效 | H29: ASITIS | I29: 0
A30: ='Command register base=0x0'!A45 -> des_opd0_lf_pad | B30: ='Command register base=0x0'!B45 -> 4 | C30: =D30+B30-1 -> 84 | D30: =C29+1 -> 81 | E30: RW | F30: ='Command register base=0x0'!F45 -> 0x0 | G30: opd0左方padding列数_x000D_, 0-15有效 | H30: ASITIS | I30: 0
A31: ='Command register base=0x0'!A46 -> des_opd0_rt_pad | B31: ='Command register base=0x0'!B46 -> 4 | C31: =D31+B31-1 -> 88 | D31: =C30+1 -> 85 | E31: RW | F31: ='Command register base=0x0'!F46 -> 0x0 | G31: opd0右方padding列数_x000D_, 0-15有效 | H31: ASITIS | I31: 0
A32: ='Command register base=0x0'!A47 -> des_res_op_x_str | B32: ='Command register base=0x0'!B47 -> 4 | C32: =D32+B32-1 -> 92 | D32: =C31+1 -> 89 | E32: RW | F32: ='Command register base=0x0'!F47 -> 0x1 | G32: 卷积/pooling横向stride, 1-15有效 | H32: ASITIS | I32: 0
A33: ='Command register base=0x0'!A48 -> des_res_op_y_str | B33: ='Command register base=0x0'!B48 -> 4 | C33: =D33+B33-1 -> 96 | D33: =C32+1 -> 93 | E33: RW | F33: ='Command register base=0x0'!F48 -> 0x1 | G33: 卷积/pooling纵向stride, 1-15有效 | H33: ASITIS | I33: 0
A34: ='Command register base=0x0'!A37 -> des_opt_opd3_const | B34: ='Command register base=0x0'!B37 -> 1 | C34: =D34+B34-1 -> 97 | D34: =C33+1 -> 97 | E34: RW | F34: ='Command register base=0x0'!F37 -> 0x0 | G34: opd3是否常数 0: 非常数 1: 常数 | H34: ASITIS | I34: 0
A35: des_short_opd0_str | B35: 3 | C35: =D35+B35-1 -> 100 | D35: =C34+1 -> 98 | E35: RW | F35: ='Command register base=0x0'!F38 -> 0x0 | G35: opd0数据存储格式 0: 对齐, 即 W_STRIDE=1 H_STRIDE=W C_STRIDE=EU_NUM*roundup(H*W/EU_NUM) N_STRIDE=C_STRIDE*roundup(C+C_START/LANE_NUM) 1: tensor others: not support | H35: ASITIS | I35: 0
A36: ='Command register base=0x0'!A76 -> des_res0_addr | B36: 26 | C36: =D36+B36-1 -> 126 | D36: =C35+1 -> 101 | E36: RW | F36: ='Command register base=0x0'!F76 -> 0x0 | G36: res0起始地址 | H36: ASITIS | I36: 0
A37: des_intr_en | B37: 1 | C37: =D37+B37-1 -> 127 | D37: =C36+1 -> 127 | E37: RW | F37: 0x0 | G37: 0: 该指令执行结束不发出intr 1: 该指令执行结束发出intr | H37: ASITIS | I37: 0
A38: ='Command register base=0x0'!A39 -> des_opd0_x_ins0 | B38: ='Command register base=0x0'!B39 -> 4 | C38: =D38+B38-1 -> 131 | D38: =C37+1 -> 128 | E38: RW | F38: ='Command register base=0x0'!F39 -> 0x0 | G38: opd0行方向每个元素后插入常数的个数, 0-14有效 | H38: ASITIS | I38: 0
A39: ='Command register base=0x0'!A40 -> des_opd0_y_ins0 | B39: ='Command register base=0x0'!B40 -> 4 | C39: =D39+B39-1 -> 135 | D39: =C38+1 -> 132 | E39: RW | F39: ='Command register base=0x0'!F40 -> 0x0 | G39: opd0列方向每个元素后插入常数的个数, 0-14有效 | H39: ASITIS | I39: 0
A40: ='Command register base=0x0'!A41 -> des_opd1_x_ins0 | B40: ='Command register base=0x0'!B41 -> 4 | C40: =D40+B40-1 -> 139 | D40: =C39+1 -> 136 | E40: RW | F40: ='Command register base=0x0'!F41 -> 0x0 | G40: opd1行方向每个元素后插入常数的个数, 0-14有效 | H40: ASITIS | I40: 0
...

Sheet sCONV_BW
A1: field | B1: Length（bit） | C1: High（bit） | D1: Low（bit） | E1: RW | F1: Default | G1: descriptions | H1: conv_neuron opd0=image opd1=kernel opd2=bias/kzp res0=result | I1: Code
A2: ='Command register base=0x0'!A2 -> des_cmd_short | B2: ='Command register base=0x0'!B2 -> 1 | C2: =D2+B2-1 -> 0 | D2: 0 | E2: RW | F2: ='Command register base=0x0'!F2 -> 0x0 | G2: 1: 512bit | H2: ASITIS | I2: 0
A3: des_sym_range | B3: 1 | C3: =D3+B3-1 -> 1 | D3: =C2+1 -> 1 | E3: RW | F3: 0x0 | G3: conv/mm2结果量化，是否做对称饱和: 0: 不做对称饱和 1: 做对称饱和 | H3: ASITIS | I3: 0
A4: des_opt_opd4_const | B4: 1 | C4: =D4+B4-1 -> 2 | D4: =C3+1 -> 2 | E4: RW | F4: 0x0 | G4: 当opd0数据类型时INT8，INT4时，KZP是否为常数 0: 非常数 1: 常数 | H4: ASITIS | I4: 0
A5: des_opt_opd5_const | B5: 1 | C5: =D5+B5-1 -> 3 | D5: =C4+1 -> 3 | E5: RW | F5: 0x0 | G5: conv/mm2结果量化，量化参数是否常数 0: 非常数 1: 常数 | H5: ASITIS | I5: 0
A6: des_opt_relu | B6: 1 | C6: =D6+B6-1 -> 4 | D6: =C5+1 -> 4 | E6: RW | F6: 0x0 | G6: 对结果是否做relu 0: 不做relu操作 1: 做relu操作 | H6: ASITIS | I6: 0
A7: des_opt_rq | B7: 1 | C7: =D7+B7-1 -> 5 | D7: =C6+1 -> 5 | E7: RW | F7: 0x0 | G7: 结果是否做量化 0: 不做量化 1: 做量化 | H7: ASITIS | I7: 0
A8: des_opd2_n_str | B8: 3 | C8: =D8+B8-1 -> 8 | D8: =C7+1 -> 6 | E8: RW | F8: ='Command register base=0x0'!F13 -> 0x0 | G8: des_opd2_n_str[2:0]: 0: round_to_even 1: half round up 2: round to zero 3: floor 4: ceil | H8: ASITIS | I8: 0
A9: des_opt_opd1_prec | B9: 3 | C9: =D9+B9-1 -> 11 | D9: =C8+1 -> 9 | E9: RW | F9: ='Command register base=0x0'!F14 -> 0x0 | G9: opd1数据类型 0: INT8 1: FP16 2: FP32 3: INT16 4: INT32 5: BFP16 6: INT4 7：FP8 | H9: ASITIS | I9: 0
A10: ='Command register base=0x0'!A3 -> des_op_code | B10: 5 | C10: =D10+B10-1 -> 16 | D10: =C9+1 -> 12 | E10: RW | F10: ='Command register base=0x0'!F3 -> 0x0 | G10: reserved0 | H10: 0 | I10: 2
A11: ='Command register base=0x0'!A4 -> des_cmd_id_dep | B11: ='Command register base=0x0'!B4 -> 23 | C11: =D11+B11-1 -> 39 | D11: =C10+1 -> 17 | E11: RW | F11: ='Command register base=0x0'!F4 -> 0x0 | G11: Dependency CMD ID 等待des_cmd_id_en指定外部eng ID完成后, 方可执行本descriptor | H11: ASITIS | I11: 0
A12: ='Command register base=0x0'!A5 -> des_dbg_mode | B12: ='Command register base=0x0'!B5 -> 1 | C12: =D12+B12-1 -> 40 | D12: =C11+1 -> 40 | E12: RW | F12: ='Command register base=0x0'!F5 -> 0x0 | G12: debug single_step des_mode | H12: ASITIS
A13: ='Command register base=0x0'!A6 -> des_tsk_typ | B13: ='Command register base=0x0'!B6 -> 4 | C13: =D13+B13-1 -> 44 | D13: =C12+1 -> 41 | E13: RW | F13: ='Command register base=0x0'!F6 -> 0x0 | G13: 指令任务类型 0: conv | H13: ASITIS | I13: 0
A14: ='Command register base=0x0'!A7 -> des_tsk_eu_typ | B14: ='Command register base=0x0'!B7 -> 5 | C14: =D14+B14-1 -> 49 | D14: =C13+1 -> 45 | E14: RW | F14: ='Command register base=0x0'!F7 -> 0x0 | G14: des_tsk_eu_typ[4:0]指令操作类型， 1: CONV_BW 4: CONV_BW_TF32 | H14: ASITIS | I14: 0
A15: ='Command register base=0x0'!A20 -> des_opt_opd0_sign | B15: ='Command register base=0x0'!B20 -> 1 | C15: =D15+B15-1 -> 50 | D15: =C14+1 -> 50 | E15: RW | F15: ='Command register base=0x0'!F20 -> 0x0 | G15: opd0数据类型是INT8时, opd0是否为有符号数 0: 无符号数 1: 有符号数 | H15: ASITIS | I15: 0
A16: des_opt_opd1_sign | B16: ='Command register base=0x0'!B21 -> 1 | C16: =D16+B16-1 -> 51 | D16: =C15+1 -> 51 | E16: RW | F16: ='Command register base=0x0'!F21 -> 0x1 | G16: opd1数据类型是INT8时, opd1是否为有符号数 0: 无符号数 1: 有符号数 | H16: ASITIS | I16: 0
A17: des_opt_opd2_sign | B17: ='Command register base=0x0'!B22 -> 1 | C17: =D17+B17-1 -> 52 | D17: =C16+1 -> 52 | E17: RW | F17: ='Command register base=0x0'!F22 -> 0x1 | G17: opd2数据类型是INT8时, opd2是否为有符号数 0: 无符号数 1: 有符号数 | H17: ASITIS | I17: 0
A18: des_pad_mode | B18: 2 | C18: =D18+B18-1 -> 54 | D18: =C17+1 -> 53 | E18: RW | F18: 0x0 | G18: padding mode: 0: Constant 1: Reflection 2: Replication 3: Circular | H18: ASITIS | I18: 0
A19: des_opt_res0_sign | B19: 1 | C19: =D19+B19-1 -> 55 | D19: =C18+1 -> 55 | E19: RW | F19: 0x0 | G19: res0是INT型时，指明结果是有符号数还是无符号数 0: 无符号 1: 有符号 结果数据类型是FP8时，opd2为152格式或143格式 0：152格式 1：143格式 | H19: ASITIS | I19: 0
A20: des_opt_opd2_prec | B20: 3 | C20: =D20+B20-1 -> 58 | D20: =C19+1 -> 56 | E20: RW | F20: ='Command register base=0x0'!F12 -> 0x0 | G20: opd2数据类型 0: INT8 1: FP16 2: FP32 3: INT16 4: INT32 5: BFP16 6: INT4 7：FP8 | H20: ASITIS | I20: 0
A21: des_pwr_step | B21: 4 | C21: =D21+B21-1 -> 62 | D21: =C20+1 -> 59 | E21: RW | F21: 0x0 | G21: power step | H21: ASITIS | I21: 0
A22: des_opt_res_add | B22: 1 | C22: =D22+B22-1 -> 63 | D22: =C21+1 -> 63 | E22: RW | F22: 0x0 | G22: 如果指令操作类型是CONV_NORMAL, 0: 不做result add 1: 做result add 其他，reserved | H22: ASITIS | I22: 0
A23: ='Command register base=0x0'!A19 -> des_opt_kernel_rotate | B23: ='Command register base=0x0'!B19 -> 1 | C23: =D23+B23-1 -> 64 | D23: =C22+1 -> 64 | E23: RW | F23: ='Command register base=0x0'!F19 -> 0x0 | G23: kernel是否旋转 | H23: ASITIS | I23: 0
A24: ='Command register base=0x0'!A23 -> des_opt_res0_prec | B24: ='Command register base=0x0'!B23 -> 3 | C24: =D24+B24-1 -> 67 | D24: =C23+1 -> 65 | E24: RW | F24: ='Command register base=0x0'!F23 -> 0x2 | G24: res0数据类型 0: INT8 1: FP16 2: FP32 3: INT16 4: INT32 5: BFP16 6: INT4 7：FP8 | H24: ASITIS | I24: 0
A25: ='Command register base=0x0'!A24 -> des_opt_opd0_prec | B25: ='Command register base=0x0'!B24 -> 3 | C25: =D25+B25-1 -> 70 | D25: =C24+1 -> 68 | E25: RW | F25: ='Command register base=0x0'!F24 -> 0x2 | G25: opd0数据类型 0: INT8 1: FP16 2: FP32 3: INT16 4: INT32 5: BFP16 6: INT4 7：FP8 | H25: ASITIS | I25: 0
A26: ='Command register base=0x0'!A28 -> des_opt_opd1_const | B26: ='Command register base=0x0'!B28 -> 1 | C26: =D26+B26-1 -> 71 | D26: =C25+1 -> 71 | E26: RW | F26: ='Command register base=0x0'!F28 -> 0x0 | G26: 0: kernel非常数 1: kernel常数 | H26: ASITIS | I26: 0
A27: ='Command register base=0x0'!A29 -> des_opt_opd2_const | B27: ='Command register base=0x0'!B29 -> 1 | C27: =D27+B27-1 -> 72 | D27: =C26+1 -> 72 | E27: RW | F27: ='Command register base=0x0'!F29 -> 0x0 | G27: 0: bias非常数 1: bias常数 | H27: ASITIS | I27: 0
A28: ='Command register base=0x0'!A43 -> des_opd0_up_pad | B28: ='Command register base=0x0'!B43 -> 4 | C28: =D28+B28-1 -> 76 | D28: =C27+1 -> 73 | E28: RW | F28: ='Command register base=0x0'!F43 -> 0x0 | G28: opd0上方padding行数_x000D_, 0-15有效 | H28: ASITIS | I28: 0
A29: ='Command register base=0x0'!A44 -> des_opd0_dn_pad | B29: ='Command register base=0x0'!B44 -> 4 | C29: =D29+B29-1 -> 80 | D29: =C28+1 -> 77 | E29: RW | F29: ='Command register base=0x0'!F44 -> 0x0 | G29: opd0下方padding行数_x000D_, 0-15有效 | H29: ASITIS | I29: 0
A30: ='Command register base=0x0'!A45 -> des_opd0_lf_pad | B30: ='Command register base=0x0'!B45 -> 4 | C30: =D30+B30-1 -> 84 | D30: =C29+1 -> 81 | E30: RW | F30: ='Command register base=0x0'!F45 -> 0x0 | G30: opd0左方padding列数_x000D_, 0-15有效 | H30: ASITIS | I30: 0
A31: ='Command register base=0x0'!A46 -> des_opd0_rt_pad | B31: ='Command register base=0x0'!B46 -> 4 | C31: =D31+B31-1 -> 88 | D31: =C30+1 -> 85 | E31: RW | F31: ='Command register base=0x0'!F46 -> 0x0 | G31: opd0右方padding列数_x000D_, 0-15有效 | H31: ASITIS | I31: 0
A32: ='Command register base=0x0'!A47 -> des_res_op_x_str | B32: ='Command register base=0x0'!B47 -> 4 | C32: =D32+B32-1 -> 92 | D32: =C31+1 -> 89 | E32: RW | F32: ='Command register base=0x0'!F47 -> 0x1 | G32: 卷积/pooling横向stride, 1-15有效 | H32: ASITIS | I32: 0
A33: ='Command register base=0x0'!A48 -> des_res_op_y_str | B33: ='Command register base=0x0'!B48 -> 4 | C33: =D33+B33-1 -> 96 | D33: =C32+1 -> 93 | E33: RW | F33: ='Command register base=0x0'!F48 -> 0x1 | G33: 卷积/pooling纵向stride, 1-15有效 | H33: ASITIS | I33: 0
A34: ='Command register base=0x0'!A37 -> des_opt_opd3_const | B34: ='Command register base=0x0'!B37 -> 1 | C34: =D34+B34-1 -> 97 | D34: =C33+1 -> 97 | E34: RW | F34: ='Command register base=0x0'!F37 -> 0x0 | G34: opd3是否常数 0: 非常数 1: 常数 | H34: ASITIS | I34: 0
A35: des_short_opd0_str | B35: 3 | C35: =D35+B35-1 -> 100 | D35: =C34+1 -> 98 | E35: RW | F35: ='Command register base=0x0'!F38 -> 0x0 | G35: opd0数据存储格式 0: 对齐, 即 W_STRIDE=1 H_STRIDE=W C_STRIDE=EU_NUM*roundup(H*W/EU_NUM) N_STRIDE=C_STRIDE*roundup(C+C_START/LANE_NUM) 1: tensor others: not support | H35: ASITIS | I35: 0
A36: ='Command register base=0x0'!A76 -> des_res0_addr | B36: 26 | C36: =D36+B36-1 -> 126 | D36: =C35+1 -> 101 | E36: RW | F36: ='Command register base=0x0'!F76 -> 0x0 | G36: res0起始地址 | H36: ASITIS | I36: 0
A37: des_intr_en | B37: 1 | C37: =D37+B37-1 -> 127 | D37: =C36+1 -> 127 | E37: RW | F37: 0x0 | G37: 0: 该指令执行结束不发出intr 1: 该指令执行结束发出intr | H37: ASITIS | I37: 0
A38: ='Command register base=0x0'!A39 -> des_opd0_x_ins0 | B38: ='Command register base=0x0'!B39 -> 4 | C38: =D38+B38-1 -> 131 | D38: =C37+1 -> 128 | E38: RW | F38: ='Command register base=0x0'!F39 -> 0x0 | G38: opd0行方向每个元素后插入常数的个数, 0-14有效 | H38: ASITIS | I38: 0
A39: ='Command register base=0x0'!A40 -> des_opd0_y_ins0 | B39: ='Command register base=0x0'!B40 -> 4 | C39: =D39+B39-1 -> 135 | D39: =C38+1 -> 132 | E39: RW | F39: ='Command register base=0x0'!F40 -> 0x0 | G39: opd0列方向每个元素后插入常数的个数, 0-14有效 | H39: ASITIS | I39: 0
A40: ='Command register base=0x0'!A41 -> des_opd1_x_ins0 | B40: ='Command register base=0x0'!B41 -> 4 | C40: =D40+B40-1 -> 139 | D40: =C39+1 -> 136 | E40: RW | F40: ='Command register base=0x0'!F41 -> 0x0 | G40: opd1行方向每个元素后插入常数的个数, 0-14有效 | H40: ASITIS | I40: 0
...

Sheet sPorD
A1: field | B1: Length（bit） | C1: High（bit） | D1: Low（bit） | E1: RW | F1: Default | G1: descriptions | H1: depthwise/pooling opd0=image opd1=kernel opd2=bias(for depth wise) | I1: code
A2: ='Command register base=0x0'!A2 -> des_cmd_short | B2: ='Command register base=0x0'!B2 -> 1 | C2: =D2+B2-1 -> 0 | D2: 0 | E2: ='Command register base=0x0'!E2 -> RW | F2: ='Command register base=0x0'!F2 -> 0x0 | G2: 1: 512bit | H2: ASITIS | I2: 0
A3: des_sym_range | B3: 1 | C3: =D3+B3-1 -> 1 | D3: =C2+1 -> 1 | E3: RW | F3: 0x0 | G3: conv/mm2结果量化，是否做对称饱和: 0: 不做对称饱和 1: 做对称饱和 | H3: ASITIS | I3: 0
A4: des_rsvd0 | B4: 1 | C4: =D4+B4-1 -> 2 | D4: =C3+1 -> 2 | E4: RW | F4: 0x0 | G4: reserved0 | H4: 0 | I4: 2
A5: des_opt_opd5_const | B5: 1 | C5: =D5+B5-1 -> 3 | D5: =C4+1 -> 3 | E5: RW | F5: 0x0 | G5: conv/mm2结果量化，量化参数是否常数 0: 非常数 1: 常数 | H5: ASITIS | I5: 0
A6: des_opt_relu | B6: 1 | C6: =D6+B6-1 -> 4 | D6: =C5+1 -> 4 | E6: RW | F6: 0x0 | G6: 对结果是否做relu 0: 不做relu操作 1: 做relu操作 | H6: ASITIS | I6: 0
A7: des_opt_rq | B7: 1 | C7: =D7+B7-1 -> 5 | D7: =C6+1 -> 5 | E7: RW | F7: 0x0 | G7: 结果是否做量化 0: 不做量化 1: 做量化 | H7: ASITIS | I7: 0
A8: ='Command register base=0x0'!A3 -> des_op_code | B8: 11 | C8: =D8+B8-1 -> 16 | D8: =C7+1 -> 6 | E8: ='Command register base=0x0'!E3 -> RW | F8: ='Command register base=0x0'!F3 -> 0x0 | G8: TPU命令ID 0不可用 | H8: ASITIS | I8: 0
A9: ='Command register base=0x0'!A4 -> des_cmd_id_dep | B9: ='Command register base=0x0'!B4 -> 23 | C9: =D9+B9-1 -> 39 | D9: =C8+1 -> 17 | E9: ='Command register base=0x0'!E4 -> RW | F9: ='Command register base=0x0'!F4 -> 0x0 | G9: Dependency CMD ID 等待des_cmd_id_en指定外部eng ID完成后, 方可执行本descriptor | H9: ASITIS | I9: 0
A10: ='Command register base=0x0'!A5 -> des_dbg_mode | B10: ='Command register base=0x0'!B5 -> 1 | C10: =D10+B10-1 -> 40 | D10: =C9+1 -> 40 | E10: ='Command register base=0x0'!E5 -> RW | F10: ='Command register base=0x0'!F5 -> 0x0 | G10: debug single_step des_mode | H10: ASITIS | I10: 0
A11: des_tsk_typ | B11: 4 | C11: =D11+B11-1 -> 44 | D11: =C10+1 -> 41 | E11: ='Command register base=0x0'!E10 -> RW | F11: ='Command register base=0x0'!F10 -> 0x0 | G11: 指令任务类型 1: depthwise or pooling | H11: ASITIS | I11: 0
A12: ='Command register base=0x0'!A7 -> des_tsk_eu_typ | B12: ='Command register base=0x0'!B7 -> 5 | C12: =D12+B12-1 -> 49 | D12: =C11+1 -> 45 | E12: ='Command register base=0x0'!E7 -> RW | F12: ='Command register base=0x0'!F7 -> 0x0 | G12: 指令操作类型 0: depthwise 1: avg pooling 3: min pooling 4: max pooling 5: ROI depthwise 6: ROI avg pooling 7: ROI max pooling 8: ROI min pooling | H12: ASITIS | I12: 0
A13: des_opt_kernel_rotate | B13: 1 | C13: =D13+B13-1 -> 50 | D13: =C12+1 -> 50 | E13: ='Command register base=0x0'!E9 -> RW | F13: ='Command register base=0x0'!F9 -> 0x2 | G13: kernel是否旋转 | H13: ASITIS | I13: 0
A14: ='Command register base=0x0'!A20 -> des_opt_opd0_sign | B14: ='Command register base=0x0'!B20 -> 1 | C14: =D14+B14-1 -> 51 | D14: =C13+1 -> 51 | E14: ='Command register base=0x0'!E20 -> RW | F14: ='Command register base=0x0'!F20 -> 0x0 | G14: opd0数据类型是INT8时, opd0是否为有符号数 0: 无符号数 1: 有符号数 | H14: ASITIS | I14: 0
A15: ='Command register base=0x0'!A21 -> des_opt_opd1_sign | B15: ='Command register base=0x0'!B21 -> 1 | C15: =D15+B15-1 -> 52 | D15: =C14+1 -> 52 | E15: ='Command register base=0x0'!E21 -> RW | F15: ='Command register base=0x0'!F21 -> 0x1 | G15: opd1数据类型是INT8时, opd0是否为有符号数 0: 无符号数 1: 有符号数 | H15: ASITIS | I15: 0
A16: ='Command register base=0x0'!A10 -> des_pad_mode | B16: ='Command register base=0x0'!B10 -> 2 | C16: =D16+B16-1 -> 54 | D16: =C15+1 -> 53 | E16: ='Command register base=0x0'!E10 -> RW | F16: ='Command register base=0x0'!F10 -> 0x0 | G16: padding mode: 0: Constant 1: Reflection 2: Replication 3: Circular | H16: ASITIS | I16: 0
A17: des_opt_res0_sign | B17: 1 | C17: =D17+B17-1 -> 55 | D17: =C16+1 -> 55 | E17: RW | F17: 0x0 | G17: res0是INT型时，指明结果是有符号数还是无符号数 0: 无符号 1: 有符号 | H17: ASITIS | I17: 0
A18: des_opt_opd2_prec | B18: ='Command register base=0x0'!B12 -> 3 | C18: =D18+B18-1 -> 58 | D18: =C17+1 -> 56 | E18: ='Command register base=0x0'!E12 -> RW | F18: ='Command register base=0x0'!F12 -> 0x0 | G18: opd2数据类型 如果指令操作类型是depthwise, 且操作数类型是INT8, 则 4: INT32 如果操作类型是ROI max pooling/ROI avg pooling/ROI depthwise 0: INT8 1: FP16 2: FP32 5: BFP16 others: reserved | H18: ASITIS | I18: 0
A19: des_pwr_step | B19: ='Command register base=0x0'!B13 -> 4 | C19: =D19+B19-1 -> 62 | D19: =C18+1 -> 59 | E19: ='Command register base=0x0'!E13 -> RW | F19: ='Command register base=0x0'!F13 -> 0x0 | G19: power step | H19: ASITIS | I19: 0
A20: ='Command register base=0x0'!A28 -> des_opt_opd1_const | B20: ='Command register base=0x0'!B28 -> 1 | C20: =D20+B20-1 -> 63 | D20: =C19+1 -> 63 | E20: ='Command register base=0x0'!E28 -> RW | F20: ='Command register base=0x0'!F28 -> 0x0 | G20: opd1是否常数, 如果是常数的话，其值在des_opd1_addr中 如果指令操作类型是avg pooling或者ROI avg pooling，则 1: 常数，即des_opd1_addr表示该常数, 该常数数据类型与opd0相同 | H20: ASITIS | I20: 0
A21: ='Command register base=0x0'!A29 -> des_opt_opd2_const | B21: ='Command register base=0x0'!B29 -> 1 | C21: =D21+B21-1 -> 64 | D21: =C20+1 -> 64 | E21: ='Command register base=0x0'!E29 -> RW | F21: ='Command register base=0x0'!F29 -> 0x0 | G21: 如果指令操作类型是ROI avg, ROI max, ROI depthwise, 则 0: 非常数 1: 常数 | H21: ASITIS | I21: 0
A22: ='Command register base=0x0'!A37 -> des_opt_opd3_const | B22: ='Command register base=0x0'!B37 -> 1 | C22: =D22+B22-1 -> 65 | D22: =C21+1 -> 65 | E22: ='Command register base=0x0'!E37 -> RW | F22: ='Command register base=0x0'!F37 -> 0x0 | G22: 如果指令操作类型是avg pooling, max pooling, depthwise, 则 padding, insert值是否常数 0: 非常数 1: 常数 如果指令操作类型是ROI avg, ROI max, ROI depthwise, 则 Fix0: 非常数 | H22: ASITIS | I22: 0
A23: ='Command register base=0x0'!A23 -> des_opt_res0_prec | B23: ='Command register base=0x0'!B23 -> 3 | C23: =D23+B23-1 -> 68 | D23: =C22+1 -> 66 | E23: ='Command register base=0x0'!E23 -> RW | F23: ='Command register base=0x0'!F23 -> 0x2 | G23: res0数据类型 0: INT8 1: FP16 2: FP32 3: INT16 4: INT32 5: BFP16 others: reserved | H23: ASITIS | I23: 0
A24: ='Command register base=0x0'!A24 -> des_opt_opd0_prec | B24: ='Command register base=0x0'!B24 -> 3 | C24: =D24+B24-1 -> 71 | D24: =C23+1 -> 69 | E24: ='Command register base=0x0'!E24 -> RW | F24: ='Command register base=0x0'!F24 -> 0x2 | G24: opd0数据类型 0: INT8 1: FP16 2: FP32 5: BFP16 others: reserved | H24: ASITIS | I24: 0
A25: ='Command register base=0x0'!A39 -> des_opd0_x_ins0 | B25: ='Command register base=0x0'!B39 -> 4 | C25: =D25+B25-1 -> 75 | D25: =C24+1 -> 72 | E25: ='Command register base=0x0'!E39 -> RW | F25: ='Command register base=0x0'!F39 -> 0x0 | G25: opd0行方向每个元素后插入0的个数, 0-7有效 | H25: ASITIS | I25: 0
A26: ='Command register base=0x0'!A40 -> des_opd0_y_ins0 | B26: ='Command register base=0x0'!B40 -> 4 | C26: =D26+B26-1 -> 79 | D26: =C25+1 -> 76 | E26: ='Command register base=0x0'!E40 -> RW | F26: ='Command register base=0x0'!F40 -> 0x0 | G26: opd0列方向每个元素后插入0的个数, 0-7有效 | H26: ASITIS | I26: 0
A27: ='Command register base=0x0'!A41 -> des_opd1_x_ins0 | B27: ='Command register base=0x0'!B41 -> 4 | C27: =D27+B27-1 -> 83 | D27: =C26+1 -> 80 | E27: ='Command register base=0x0'!E41 -> RW | F27: ='Command register base=0x0'!F41 -> 0x0 | G27: opd1行方向每个元素后插入0的个数, 0-14有效 | H27: ASITIS | I27: 0
A28: ='Command register base=0x0'!A42 -> des_opd1_y_ins0 | B28: ='Command register base=0x0'!B42 -> 4 | C28: =D28+B28-1 -> 87 | D28: =C27+1 -> 84 | E28: ='Command register base=0x0'!E42 -> RW | F28: ='Command register base=0x0'!F42 -> 0x0 | G28: opd1列方向每个元素后插入0的个数, 0-14有效 | H28: ASITIS | I28: 0
A29: ='Command register base=0x0'!A43 -> des_opd0_up_pad | B29: ='Command register base=0x0'!B43 -> 4 | C29: =D29+B29-1 -> 91 | D29: =C28+1 -> 88 | E29: ='Command register base=0x0'!E43 -> RW | F29: ='Command register base=0x0'!F43 -> 0x0 | G29: opd0上方padding行数_x000D_, 0-15有效 | H29: ASITIS | I29: 0
A30: ='Command register base=0x0'!A44 -> des_opd0_dn_pad | B30: ='Command register base=0x0'!B44 -> 4 | C30: =D30+B30-1 -> 95 | D30: =C29+1 -> 92 | E30: ='Command register base=0x0'!E44 -> RW | F30: ='Command register base=0x0'!F44 -> 0x0 | G30: opd0下方padding行数_x000D_, 0-15有效 | H30: ASITIS | I30: 0
A31: ='Command register base=0x0'!A45 -> des_opd0_lf_pad | B31: ='Command register base=0x0'!B45 -> 4 | C31: =D31+B31-1 -> 99 | D31: =C30+1 -> 96 | E31: ='Command register base=0x0'!E45 -> RW | F31: ='Command register base=0x0'!F45 -> 0x0 | G31: opd0左方padding列数_x000D_, 0-15有效 | H31: ASITIS | I31: 0
A32: ='Command register base=0x0'!A46 -> des_opd0_rt_pad | B32: ='Command register base=0x0'!B46 -> 4 | C32: =D32+B32-1 -> 103 | D32: =C31+1 -> 100 | E32: ='Command register base=0x0'!E46 -> RW | F32: ='Command register base=0x0'!F46 -> 0x0 | G32: opd0右方padding列数_x000D_, 0-15有效 | H32: ASITIS | I32: 0
A33: ='Command register base=0x0'!A47 -> des_res_op_x_str | B33: ='Command register base=0x0'!B47 -> 4 | C33: =D33+B33-1 -> 107 | D33: =C32+1 -> 104 | E33: ='Command register base=0x0'!E47 -> RW | F33: ='Command register base=0x0'!F47 -> 0x1 | G33: 卷积/pooling横向stride, 1-15有效 | H33: ASITIS | I33: 0
A34: ='Command register base=0x0'!A48 -> des_res_op_y_str | B34: ='Command register base=0x0'!B48 -> 4 | C34: =D34+B34-1 -> 111 | D34: =C33+1 -> 108 | E34: ='Command register base=0x0'!E48 -> RW | F34: ='Command register base=0x0'!F48 -> 0x1 | G34: 卷积/pooling纵向stride, 1-15有效 | H34: ASITIS | I34: 0
A35: des_opd2_n_str | B35: 3 | C35: =D35+B35-1 -> 114 | D35: =C34+1 -> 112 | E35: RW | F35: 0x0 | G35: des_opd2_n_str[2:0]: 如果指令操作类型是depthwise, depthwise_relu且是INT8运算, round模式 0: round_to_even 1: half round up 2: round to zero 3: floor 4: ceil 5: round to nearest with Ties to Plus Infinity 6: round to nearest with Ties to Minus Infinity | H35: ASITIS | I35: 0
A36: des_rsvd2 | B36: 11 | C36: =D36+B36-1 -> 125 | D36: =C35+1 -> 115 | E36: ='Command register base=0x0'!E37 -> RW | F36: ='Command register base=0x0'!F37 -> 0x0 | G36: reserved0 | H36: 0 | I36: 2
A37: des_opt_opd2_sign | B37: 1 | C37: =D37+B37-1 -> 126 | D37: =C36+1 -> 126 | E37: ='Command register base=0x0'!E37 -> RW | F37: ='Command register base=0x0'!F37 -> 0x0 | G37: opd2符号位 | H37: ASITIS | I37: 0
A38: des_intr_en | B38: 1 | C38: =D38+B38-1 -> 127 | D38: =C37+1 -> 127 | E38: ='Command register base=0x0'!E38 -> RW | F38: ='Command register base=0x0'!F38 -> 0x0 | G38: 0: 该指令执行结束不发出intr 1: 该指令执行结束发出intr | H38: ASITIS | I38: 0
A39: ='Command register base=0x0'!A56 -> des_res0_n | B39: ='Command register base=0x0'!B56 -> 16 | C39: =D39+B39-1 -> 143 | D39: =C38+1 -> 128 | E39: ='Command register base=0x0'!E56 -> RW | F39: ='Command register base=0x0'!F56 -> 0x1 | G39: res0的n, 0无效 | H39: ASITIS | I39: 0
A40: ='Command register base=0x0'!A57 -> des_res0_c | B40: ='Command register base=0x0'!B57 -> 16 | C40: =D40+B40-1 -> 159 | D40: =C39+1 -> 144 | E40: ='Command register base=0x0'!E57 -> RW | F40: ='Command register base=0x0'!F57 -> 0x1 | G40: res0的c, 0无效 | H40: ASITIS | I40: 0
...

Sheet sMM
A1: field | B1: Length（bit） | C1: High（bit） | D1: Low（bit） | E1: RW | F1: Default | G1: descriptions | H1: matrix | I1: code
A2: ='Command register base=0x0'!A2 -> des_cmd_short | B2: ='Command register base=0x0'!B2 -> 1 | C2: =D2+B2-1 -> 0 | D2: 0 | E2: ='Command register base=0x0'!E2 -> RW | F2: ='Command register base=0x0'!F2 -> 0x0 | G2: 1: 384bit | H2: ASITIS | I2: 0
A3: des_sym_range | B3: 1 | C3: =D3+B3-1 -> 1 | D3: =C2+1 -> 1 | E3: RW | F3: 0x0 | G3: 量化饱和是否做对称饱和 | H3: ASITIS | I3: 0
A4: des_rsvd0 | B4: 1 | C4: =D4+B4-1 -> 2 | D4: =C3+1 -> 2 | E4: RW | F4: 0x0 | G4: reserved0 | H4: 0 | I4: 2
A5: des_rsvd1 | B5: 1 | C5: =D5+B5-1 -> 3 | D5: =C4+1 -> 3 | E5: RW | F5: 0x0 | G5: reserved0 | H5: 0 | I5: 2
A6: des_opt_relu | B6: 1 | C6: =D6+B6-1 -> 4 | D6: =C5+1 -> 4 | E6: RW | F6: 0x0 | G6: 对结果是否做relu 0: 不做relu操作 1: 做relu操作 | H6: ASITIS | I6: 0
A7: des_opt_rq | B7: 1 | C7: =D7+B7-1 -> 5 | D7: =C6+1 -> 5 | E7: RW | F7: 0x0 | G7: 结果是否做量化 0: 不做量化 1: 做量化 | H7: ASITIS | I7: 0
A8: des_rsvd2 | B8: 3 | C8: =D8+B8-1 -> 8 | D8: =C7+1 -> 6 | E8: RW | F8: ='Command register base=0x0'!F13 -> 0x0 | G8: reserved0 | H8: 0 | I8: 2
A9: des_rsvd3 | B9: 8 | C9: =D9+B9-1 -> 16 | D9: =C8+1 -> 9 | E9: ='Command register base=0x0'!E3 -> RW | F9: ='Command register base=0x0'!F3 -> 0x0 | G9: reserved0 | H9: 0 | I9: 2
A10: ='Command register base=0x0'!A4 -> des_cmd_id_dep | B10: ='Command register base=0x0'!B4 -> 23 | C10: =D10+B10-1 -> 39 | D10: =C9+1 -> 17 | E10: ='Command register base=0x0'!E4 -> RW | F10: ='Command register base=0x0'!F4 -> 0x0 | G10: Dependency CMD ID 等待des_cmd_id_en指定外部eng ID完成后, 方可执行本descriptor | H10: ASITIS | I10: 0
A11: ='Command register base=0x0'!A5 -> des_dbg_mode | B11: ='Command register base=0x0'!B5 -> 1 | C11: =D11+B11-1 -> 40 | D11: =C10+1 -> 40 | E11: ='Command register base=0x0'!E5 -> RW | F11: ='Command register base=0x0'!F5 -> 0x0 | G11: debug single_step des_mode | H11: ASITIS | I11: 0
A12: ='Command register base=0x0'!A6 -> des_tsk_typ | B12: ='Command register base=0x0'!B6 -> 4 | C12: =D12+B12-1 -> 44 | D12: =C11+1 -> 41 | E12: ='Command register base=0x0'!E6 -> RW | F12: ='Command register base=0x0'!F6 -> 0x0 | G12: 指令任务类型 2: matrix multiply && matrix multiply2 | H12: ASITIS | I12: 0
A13: ='Command register base=0x0'!A7 -> des_tsk_eu_typ | B13: 5 | C13: =D13+B13-1 -> 49 | D13: =C12+1 -> 45 | E13: ='Command register base=0x0'!E7 -> RW | F13: ='Command register base=0x0'!F7 -> 0x0 | G13: 指令操作类型 1: MM_NORMAL others: not support | H13: ASITIS | I13: 0
A14: des_opt_res_add | B14: 1 | C14: =D14+B14-1 -> 50 | D14: =C13+1 -> 50 | E14: RW | F14: 0x0 | G14: 是否result_add | H14: ASITIS | I14: 0
A15: ='Command register base=0x0'!A17 -> des_opt_left_tran | B15: ='Command register base=0x0'!B17 -> 1 | C15: =D15+B15-1 -> 51 | D15: =C14+1 -> 51 | E15: ='Command register base=0x0'!E17 -> RW | F15: ='Command register base=0x0'!F17 -> 0x0 | G15: 如果指令操作类型是MM_NORMAL, 左矩阵是否转置 0: 不转置 1: 转置 | H15: ASITIS | I15: 0
A16: des_opt_opd0_const | B16: ='Command register base=0x0'!B28 -> 1 | C16: =D16+B16-1 -> 52 | D16: =C15+1 -> 52 | E16: ='Command register base=0x0'!E28 -> RW | F16: ='Command register base=0x0'!F28 -> 0x0 | G16: opd0是否常数 0: 非常数 1: 常数 | H16: ASITIS | I16: 0
A17: ='Command register base=0x0'!A29 -> des_opt_opd2_const | B17: ='Command register base=0x0'!B29 -> 1 | C17: =D17+B17-1 -> 53 | D17: =C16+1 -> 53 | E17: ='Command register base=0x0'!E29 -> RW | F17: ='Command register base=0x0'!F29 -> 0x0 | G17: opd2是否常数 0: 非常数 1: 常数 | H17: ASITIS | I17: 0
A18: des_rsvd4 | B18: 1 | C18: =D18+B18-1 -> 54 | D18: =C17+1 -> 54 | E18: RW | F18: 0x0 | G18: reserved0 | H18: 0 | I18: 2
A19: ='Command register base=0x0'!A11 -> des_opt_res0_sign | B19: 1 | C19: =D19+B19-1 -> 55 | D19: =C18+1 -> 55 | E19: ='Command register base=0x0'!E11 -> RW | F19: ='Command register base=0x0'!F11 -> 0x0 | G19: res0是INT型时，指明结果是有符号数还是无符号数 0: 无符号 1: 有符号 | H19: ASITIS | I19: 0
A20: des_rsvd5 | B20: 3 | C20: =D20+B20-1 -> 58 | D20: =C19+1 -> 56 | E20: ='Command register base=0x0'!E12 -> RW | F20: ='Command register base=0x0'!F12 -> 0x0 | G20: reserved0 | H20: 0 | I20: 2
A21: des_pwr_step | B21: 4 | C21: =D21+B21-1 -> 62 | D21: =C20+1 -> 59 | E21: ='Command register base=0x0'!E27 -> RW | F21: ='Command register base=0x0'!F27 -> 0x0 | G21: power step | H21: ASITIS | I21: 0
A22: des_intr_en | B22: 1 | C22: =D22+B22-1 -> 63 | D22: =C21+1 -> 63 | E22: RW | F22: 0x0 | G22: 0: 该指令执行结束不发出intr 1: 该指令执行结束发出intr | H22: ASITIS | I22: 0
A23: ='Command register base=0x0'!A20 -> des_opt_opd0_sign | B23: ='Command register base=0x0'!B20 -> 1 | C23: =D23+B23-1 -> 64 | D23: =C22+1 -> 64 | E23: ='Command register base=0x0'!E20 -> RW | F23: ='Command register base=0x0'!F20 -> 0x0 | G23: opd0数据类型是INT8时，opd0是否为有符号数 0: 无符号数 1: 有符号数 | H23: ASITIS | I23: 0
A24: ='Command register base=0x0'!A21 -> des_opt_opd1_sign | B24: ='Command register base=0x0'!B21 -> 1 | C24: =D24+B24-1 -> 65 | D24: =C23+1 -> 65 | E24: ='Command register base=0x0'!E21 -> RW | F24: ='Command register base=0x0'!F21 -> 0x1 | G24: opd1数据类型是INT8时，opd0是否为有符号数 0: 无符号数 1: 有符号数 | H24: ASITIS | I24: 0
A25: des_opt_opd2_sign | B25: 1 | C25: =D25+B25-1 -> 66 | D25: =C24+1 -> 66 | E25: RW | F25: 0x1 | G25: opd2是否为有符号数 如果指令操作类型是MM_NORMAL, 且opd0数据类型是INT32时 0: 无符号数 如果指令操作类型是NM_NORMAL, 且opd0数据类型是INT8/INT16, 则 0: 无符号数 1: 有符号数 | H25: ASITIS | I25: 0
A26: ='Command register base=0x0'!A23 -> des_opt_res0_prec | B26: ='Command register base=0x0'!B23 -> 3 | C26: =D26+B26-1 -> 69 | D26: =C25+1 -> 67 | E26: ='Command register base=0x0'!E23 -> RW | F26: ='Command register base=0x0'!F23 -> 0x2 | G26: res0数据类型 0: INT8 2: FP32 3: INT16 4: INT32 others: reserved | H26: ASITIS | I26: 0
A27: ='Command register base=0x0'!A24 -> des_opt_opd0_prec | B27: ='Command register base=0x0'!B24 -> 3 | C27: =D27+B27-1 -> 72 | D27: =C26+1 -> 70 | E27: ='Command register base=0x0'!E24 -> RW | F27: ='Command register base=0x0'!F24 -> 0x2 | G27: opd0数据类型 0: INT8 2: FP32 3: INT16 4: INT32 others: reserved | H27: ASITIS | I27: 0
